Workbook

Sheet 期望1
A1: 干员 | B1: 主能力 | C1: 副能力 | D1: 怪物抗性 | G1: 暴击伤害 | H1: 非暴击伤害 | I1: 期望伤害 | J1: 次数 | K1: 技能名 | L1: 增益1 | M1: 增益2 | N1: 增益3 | O1: 增益4 | P1: 增益5 | Q1: 增益6 | R1: 增益7 | S1: 增益8 | T1: 增益9 | U1: 增益10 | V1: 增益11 | W1: 增益12 | X1: 增益13 | Y1: 增益14 | Z1: 增益15 | AA1: 倍率 | AB1: 攻击加成 | AC1: 即时攻击 | AD1: 暴击 | AE1: 暴击伤害 | AF1: 伤害加成 | AG1: 源石技艺加成 | AH1: 增幅加成 | AI1: 脆弱加成 | AJ1: 易伤加成 | AK1: 失衡易伤加成 | AL1: 抗性 | AM1: 连击加成 | AN1: 特殊加成
A2: 弭弗0-1潜 | B2: =VLOOKUP($A$2,干员属性!$A:$AG,24,FALSE) -> 力量 | C2: =VLOOKUP($A$2,干员属性!$A:$AG,25,FALSE) -> 意志 | D2: 0 | G2: =AA2*AC2*(1+AF2)*(1+AG2)*(1+AH2)*(1+AI2)*(1+AJ2)*(1+AK2)*(1-$D$2+AL2)*(1+AM2)*(1+AN2)*0.5*AE2*J2 -> 223161.64 | H2: =AA2*AC2*(1+AF2)*(1+AG2)*(1+AH2)*(1+AI2)*(1+AJ2)*(1+AK2)*(1-$D$2+AL2)*(1+AM2)*(1+AN2)*0.5*J2 -> 148774.43 | I2: =AA2*AC2*(1+AF2)*(1+AG2)*(1+AH2)*(1+AI2)*(1+AJ2)*(1+AK2)*(1-$D$2+AL2)*(1+AM2)*(1+AN2)*0.5*(AE2*AD2+(1-AD2))*J2 -> 160676.38 | J2: 1 | K2: 3层猛击 | L2: 旧锋3层翻倍 | M2: 弭弗连携脆弱0潜 | N2: 弭弗专武+强度0潜 | O2: 弭弗专武+物伤3层0潜 | P2: N/a | Q2: N/a | R2: N/a | S2: N/a | T2: N/a | U2: N/a | V2: N/a | W2: N/a | X2: N/a | Y2: N/a | Z2: N/a | AA2: =VLOOKUP(K2,技能属性!$A:$AB,2,FALSE) -> 6 | AB2: {=$C$8+SUM(_xlfn.XLOOKUP(L2:Z2,增益属性!$A:$A,增益属性!$N:$N,0))} -> 0.47 | AC2: {=($C$7*(1+AB2)+$C$27)*(1+(INT((VLOOKUP(VLOOKUP($A$2,干员属性!$A:$AB,24,FALSE),$B$3:$C$6,2,FALSE)/(1+$C$24)*(1+$C$24+SUM(_xlfn.XLOOKUP(L2:Z2,增益属性!$A:$A,增益属性!$O:$O,0)))))*0.5+INT(VLOOKUP(VLOOKUP($A$2,干员属性!$A:$AB,25,FALSE),$B$3:$C$6,2,FALSE)*(1+SUM(_xlfn.XLOOKUP(L2:Z2,增益属性!$A:$A,增益属性!$O:$O,0))))*0.2+(INT(IFERROR(VLOOKUP(VLOOKUP($A$2,干员属性!$A:$AB,26,FALSE),$B$3:$C$6,2,FALSE),0)/(1+$C$25)*(1+$C$25+SUM(_xlfn.XLOOKUP(L2:Z2,增益属性!$A:$A,增益属性!$O:$O,0))))+INT(IFERROR(VLOOKUP(VLOOKUP($A$2,干员属性!$A:$AB,27,FALSE),$B$3:$C$6,2,FALSE),0)*(1+SUM(_xlfn.XLOOKUP(L2:Z2,增益属性!$A:$A,增益属性!$O:$O,0)))))*VLOOKUP($A$2,干员属性!$A:$AB,28,FALSE))/100)} -> 6896.898 | AD2: {=$C$10+VLOOKUP(K2,技能属性!$A:$Z,3,FALSE)+SUM(_xlfn.XLOOKUP(L2:Z2,增益属性!$A:$A,增益属性!$B:$B))} -> 0.16 | AE2: {=$C$11+VLOOKUP(K2,技能属性!$A:$AB,4,FALSE)+SUM(_xlfn.XLOOKUP(L2:Z2,增益属性!$A:$A,增益属性!$C:$C))} -> 1.5 | AF2: {=VLOOKUP(VLOOKUP(K2,技能属性!$A:$Z,5,FALSE),$B$14:$C$18,2,FALSE)+SUM(_xlfn.XLOOKUP(L2:Z2,增益属性!$A:$A,增益属性!$D:$D))+SUM(_xlfn.XLOOKUP(L2:Z2,增益属性!$A:$A,增益属性!$E:$E))+IF(VLOOKUP(K2,技能属性!$A:$Z,6,FALSE)="无",0,VLOOKUP(VLOOKUP(K2,技能属性!$A:$Z,6,FALSE),$B$20:$C$23,2,FALSE))+IF(VLOOKUP(K2,技能属性!$A:$Z,7,FALSE)=0,0,$C$19)} -> 1.2625 | AG2: {=IF(VLOOKUP(K2,技能属性!$A:$Z,8,FALSE)=0,0,$C$12+SUM(_xlfn.XLOOKUP(L2:Z2,增益属性!$A:$A,增益属性!$F:$F)))} -> 1.4667 | AH2: {=VLOOKUP(K2,技能属性!$A:$Z,9,FALSE)+SUM(_xlfn.XLOOKUP(L2:Z2,增益属性!$A:$A,增益属性!$G:$G))} -> 0 | AI2: {=VLOOKUP(K2,技能属性!$A:$Z,10,FALSE)+SUM(_xlfn.XLOOKUP(L2:Z2,增益属性!$A:$A,增益属性!$H:$H))} -> 0.05 | AJ2: {=VLOOKUP(K2,技能属性!$A:$Z,11,FALSE)+SUM(_xlfn.XLOOKUP(L2:Z2,增益属性!$A:$A,增益属性!$I:$I))} -> 0 | AK2: {=VLOOKUP(K2,技能属性!$A:$Z,12,FALSE)+SUM(_xlfn.XLOOKUP(L2:Z2,增益属性!$A:$A,增益属性!$J:$J))} -> 0 | AL2: {=VLOOKUP(K2,技能属性!$A:$Z,13,FALSE)+SUM(_xlfn.XLOOKUP(L2:Z2,增益属性!$A:$A,增益属性!$K:$K))} -> 0 | AM2: {=VLOOKUP(K2,技能属性!$A:$Z,14,FALSE)+SUM(_xlfn.XLOOKUP(L2:Z2,增益属性!$A:$A,增益属性!$L:$L))} -> 0 | AN2: {=VLOOKUP(K2,技能属性!$A:$Z,15,FALSE)+SUM(_xlfn.XLOOKUP(L2:Z2,增益属性!$A:$A,增益属性!$M:$M))} -> 0.22704082
A3: 武器 | B3: 力量 | C3: =(VLOOKUP($A$2,干员属性!$A:$AG,3,FALSE)+IF(B3=B2,VLOOKUP($A$4,武器属性!$A:$AB,3,FALSE),0)+IF(B3=C2,VLOOKUP($A$4,武器属性!$A:$AB,4,FALSE),0)+VLOOKUP($A$4,武器属性!$A:$AB,5,FALSE)+VLOOKUP($A$6,护甲属性!$A:$Z,3,FALSE)+VLOOKUP($A$8,护手属性!$A:$Z,3,FALSE)+VLOOKUP($A$10,配件属性!$A:$Z,3,FALSE)+VLOOKUP($A$12,配件属性!$A:$Z,3,FALSE)+VLOOKUP($A$14,套装属性!$A:$Z,3,FALSE)+VLOOKUP($A$16,食物属性!$A:$Z,3,FALSE))*(1+(IF(B2="力量",C24,0)+IF(C2="力量",C25,0))) -> 680.46 | G3: =AA3*AC3*(1+AF3)*(1+AG3)*(1+AH3)*(1+AI3)*(1+AJ3)*(1+AK3)*(1-$D$2+AL3)*(1+AM3)*(1+AN3)*0.5*AE3*J3 -> 24576.665 | H3: =AA3*AC3*(1+AF3)*(1+AG3)*(1+AH3)*(1+AI3)*(1+AJ3)*(1+AK3)*(1-$D$2+AL3)*(1+AM3)*(1+AN3)*0.5*J3 -> 16384.443 | I3: =AA3*AC3*(1+AF3)*(1+AG3)*(1+AH3)*(1+AI3)*(1+AJ3)*(1+AK3)*(1-$D$2+AL3)*(1+AM3)*(1+AN3)*0.5*(AE3*AD3+(1-AD3))*J3 -> 17695.199 | J3: 1 | K3: 弭弗战技二(0-4潜) | L3: 旧锋3层翻倍 | M3: 弭弗连携脆弱0潜 | N3: 弭弗专武+强度0潜 | O3: 弭弗专武+物伤3层0潜 | P3: N/a | Q3: N/a | R3: N/a | S3: N/a | T3: N/a | U3: N/a | V3: N/a | W3: N/a | X3: N/a | Y3: N/a | Z3: N/a | AA3: =VLOOKUP(K3,技能属性!$A:$AB,2,FALSE) -> 2 | AB3: {=$C$8+SUM(_xlfn.XLOOKUP(L3:Z3,增益属性!$A:$A,增益属性!$N:$N,0))} -> 0.47 | AC3: {=($C$7*(1+AB3)+$C$27)*(1+(INT((VLOOKUP(VLOOKUP($A$2,干员属性!$A:$AB,24,FALSE),$B$3:$C$6,2,FALSE)/(1+$C$24)*(1+$C$24+SUM(_xlfn.XLOOKUP(L3:Z3,增益属性!$A:$A,增益属性!$O:$O,0)))))*0.5+INT(VLOOKUP(VLOOKUP($A$2,干员属性!$A:$AB,25,FALSE),$B$3:$C$6,2,FALSE)*(1+SUM(_xlfn.XLOOKUP(L3:Z3,增益属性!$A:$A,增益属性!$O:$O,0))))*0.2+(INT(IFERROR(VLOOKUP(VLOOKUP($A$2,干员属性!$A:$AB,26,FALSE),$B$3:$C$6,2,FALSE),0)/(1+$C$25)*(1+$C$25+SUM(_xlfn.XLOOKUP(L3:Z3,增益属性!$A:$A,增益属性!$O:$O,0))))+INT(IFERROR(VLOOKUP(VLOOKUP($A$2,干员属性!$A:$AB,27,FALSE),$B$3:$C$6,2,FALSE),0)*(1+SUM(_xlfn.XLOOKUP(L3:Z3,增益属性!$A:$A,增益属性!$O:$O,0)))))*VLOOKUP($A$2,干员属性!$A:$AB,28,FALSE))/100)} -> 6896.898 | AD3: {=$C$10+VLOOKUP(K3,技能属性!$A:$Z,3,FALSE)+SUM(_xlfn.XLOOKUP(L3:Z3,增益属性!$A:$A,增益属性!$B:$B))} -> 0.16 | AE3: {=$C$11+VLOOKUP(K3,技能属性!$A:$AB,4,FALSE)+SUM(_xlfn.XLOOKUP(L3:Z3,增益属性!$A:$A,增益属性!$C:$C))} -> 1.5 | AF3: {=VLOOKUP(VLOOKUP(K3,技能属性!$A:$Z,5,FALSE),$B$14:$C$18,2,FALSE)+SUM(_xlfn.XLOOKUP(L3:Z3,增益属性!$A:$A,增益属性!$D:$D))+SUM(_xlfn.XLOOKUP(L3:Z3,增益属性!$A:$A,增益属性!$E:$E))+IF(VLOOKUP(K3,技能属性!$A:$Z,6,FALSE)="无",0,VLOOKUP(VLOOKUP(K3,技能属性!$A:$Z,6,FALSE),$B$20:$C$23,2,FALSE))+IF(VLOOKUP(K3,技能属性!$A:$Z,7,FALSE)=0,0,$C$19)} -> 1.2625 | AG3: {=IF(VLOOKUP(K3,技能属性!$A:$Z,8,FALSE)=0,0,$C$12+SUM(_xlfn.XLOOKUP(L3:Z3,增益属性!$A:$A,增益属性!$F:$F)))} -> 0 | AH3: {=VLOOKUP(K3,技能属性!$A:$Z,9,FALSE)+SUM(_xlfn.XLOOKUP(L3:Z3,增益属性!$A:$A,增益属性!$G:$G))} -> 0 | AI3: {=VLOOKUP(K3,技能属性!$A:$Z,10,FALSE)+SUM(_xlfn.XLOOKUP(L3:Z3,增益属性!$A:$A,增益属性!$H:$H))} -> 0.05 | AJ3: {=VLOOKUP(K3,技能属性!$A:$Z,11,FALSE)+SUM(_xlfn.XLOOKUP(L3:Z3,增益属性!$A:$A,增益属性!$I:$I))} -> 0 | AK3: {=VLOOKUP(K3,技能属性!$A:$Z,12,FALSE)+SUM(_xlfn.XLOOKUP(L3:Z3,增益属性!$A:$A,增益属性!$J:$J))} -> 0 | AL3: {=VLOOKUP(K3,技能属性!$A:$Z,13,FALSE)+SUM(_xlfn.XLOOKUP(L3:Z3,增益属性!$A:$A,增益属性!$K:$K))} -> 0 | AM3: {=VLOOKUP(K3,技能属性!$A:$Z,14,FALSE)+SUM(_xlfn.XLOOKUP(L3:Z3,增益属性!$A:$A,增益属性!$L:$L))} -> 0 | AN3: {=VLOOKUP(K3,技能属性!$A:$Z,15,FALSE)+SUM(_xlfn.XLOOKUP(L3:Z3,增益属性!$A:$A,增益属性!$M:$M))} -> 0
A4: 赤缨0潜 | B4: 敏捷 | C4: =(VLOOKUP($A$2,干员属性!$A:$AG,4,FALSE)+IF(B4=B2,VLOOKUP($A$4,武器属性!$A:$AB,3,FALSE),0)+IF(B4=C2,VLOOKUP($A$4,武器属性!$A:$AB,4,FALSE),0)+VLOOKUP($A$4,武器属性!$A:$AB,6,FALSE)+VLOOKUP($A$6,护甲属性!$A:$Z,4,FALSE)+VLOOKUP($A$8,护手属性!$A:$Z,4,FALSE)+VLOOKUP($A$10,配件属性!$A:$Z,4,FALSE)+VLOOKUP($A$12,配件属性!$A:$Z,4,FALSE)+VLOOKUP($A$14,套装属性!$A:$Z,4,FALSE)+VLOOKUP($A$16,食物属性!$A:$Z,4,FALSE))*(1+(IF(B2="敏捷",C24,0)+IF(C2="敏捷",C25,0))) -> 92.94 | D4: 轴长 | E4: 1 | G4: =AA4*AC4*(1+AF4)*(1+AG4)*(1+AH4)*(1+AI4)*(1+AJ4)*(1+AK4)*(1-$D$2+AL4)*(1+AM4)*(1+AN4)*0.5*AE4*J4 -> 218243.73 | H4: =AA4*AC4*(1+AF4)*(1+AG4)*(1+AH4)*(1+AI4)*(1+AJ4)*(1+AK4)*(1-$D$2+AL4)*(1+AM4)*(1+AN4)*0.5*J4 -> 145495.82 | I4: =AA4*AC4*(1+AF4)*(1+AG4)*(1+AH4)*(1+AI4)*(1+AJ4)*(1+AK4)*(1-$D$2+AL4)*(1+AM4)*(1+AN4)*0.5*(AE4*AD4+(1-AD4))*J4 -> 157135.49 | J4: 1 | K4: 弭弗战技三(0-4潜) | L4: 旧锋3层翻倍 | M4: 弭弗连携脆弱0潜 | N4: 弭弗专武+强度0潜 | O4: 弭弗专武+物伤3层0潜 | P4: N/a | Q4: N/a | R4: N/a | S4: N/a | T4: N/a | U4: N/a | V4: N/a | W4: N/a | X4: N/a | Y4: N/a | Z4: N/a | AA4: =VLOOKUP(K4,技能属性!$A:$AB,2,FALSE) -> 6 | AB4: {=$C$8+SUM(_xlfn.XLOOKUP(L4:Z4,增益属性!$A:$A,增益属性!$N:$N,0))} -> 0.47 | AC4: {=($C$7*(1+AB4)+$C$27)*(1+(INT((VLOOKUP(VLOOKUP($A$2,干员属性!$A:$AB,24,FALSE),$B$3:$C$6,2,FALSE)/(1+$C$24)*(1+$C$24+SUM(_xlfn.XLOOKUP(L4:Z4,增益属性!$A:$A,增益属性!$O:$O,0)))))*0.5+INT(VLOOKUP(VLOOKUP($A$2,干员属性!$A:$AB,25,FALSE),$B$3:$C$6,2,FALSE)*(1+SUM(_xlfn.XLOOKUP(L4:Z4,增益属性!$A:$A,增益属性!$O:$O,0))))*0.2+(INT(IFERROR(VLOOKUP(VLOOKUP($A$2,干员属性!$A:$AB,26,FALSE),$B$3:$C$6,2,FALSE),0)/(1+$C$25)*(1+$C$25+SUM(_xlfn.XLOOKUP(L4:Z4,增益属性!$A:$A,增益属性!$O:$O,0))))+INT(IFERROR(VLOOKUP(VLOOKUP($A$2,干员属性!$A:$AB,27,FALSE),$B$3:$C$6,2,FALSE),0)*(1+SUM(_xlfn.XLOOKUP(L4:Z4,增益属性!$A:$A,增益属性!$O:$O,0)))))*VLOOKUP($A$2,干员属性!$A:$AB,28,FALSE))/100)} -> 6896.898 | AD4: {=$C$10+VLOOKUP(K4,技能属性!$A:$Z,3,FALSE)+SUM(_xlfn.XLOOKUP(L4:Z4,增益属性!$A:$A,增益属性!$B:$B))} -> 0.16 | AE4: {=$C$11+VLOOKUP(K4,技能属性!$A:$AB,4,FALSE)+SUM(_xlfn.XLOOKUP(L4:Z4,增益属性!$A:$A,增益属性!$C:$C))} -> 1.5 | AF4: {=VLOOKUP(VLOOKUP(K4,技能属性!$A:$Z,5,FALSE),$B$14:$C$18,2,FALSE)+SUM(_xlfn.XLOOKUP(L4:Z4,增益属性!$A:$A,增益属性!$D:$D))+SUM(_xlfn.XLOOKUP(L4:Z4,增益属性!$A:$A,增益属性!$E:$E))+IF(VLOOKUP(K4,技能属性!$A:$Z,6,FALSE)="无",0,VLOOKUP(VLOOKUP(K4,技能属性!$A:$Z,6,FALSE),$B$20:$C$23,2,FALSE))+IF(VLOOKUP(K4,技能属性!$A:$Z,7,FALSE)=0,0,$C$19)} -> 1.2625 | AG4: {=IF(VLOOKUP(K4,技能属性!$A:$Z,8,FALSE)=0,0,$C$12+SUM(_xlfn.XLOOKUP(L4:Z4,增益属性!$A:$A,增益属性!$F:$F)))} -> 1.4667 | AH4: {=VLOOKUP(K4,技能属性!$A:$Z,9,FALSE)+SUM(_xlfn.XLOOKUP(L4:Z4,增益属性!$A:$A,增益属性!$G:$G))} -> 0 | AI4: {=VLOOKUP(K4,技能属性!$A:$Z,10,FALSE)+SUM(_xlfn.XLOOKUP(L4:Z4,增益属性!$A:$A,增益属性!$H:$H))} -> 0.05 | AJ4: {=VLOOKUP(K4,技能属性!$A:$Z,11,FALSE)+SUM(_xlfn.XLOOKUP(L4:Z4,增益属性!$A:$A,增益属性!$I:$I))} -> 0 | AK4: {=VLOOKUP(K4,技能属性!$A:$Z,12,FALSE)+SUM(_xlfn.XLOOKUP(L4:Z4,增益属性!$A:$A,增益属性!$J:$J))} -> 0 | AL4: {=VLOOKUP(K4,技能属性!$A:$Z,13,FALSE)+SUM(_xlfn.XLOOKUP(L4:Z4,增益属性!$A:$A,增益属性!$K:$K))} -> 0 | AM4: {=VLOOKUP(K4,技能属性!$A:$Z,14,FALSE)+SUM(_xlfn.XLOOKUP(L4:Z4,增益属性!$A:$A,增益属性!$L:$L))} -> 0 | AN4: {=VLOOKUP(K4,技能属性!$A:$Z,15,FALSE)+SUM(_xlfn.XLOOKUP(L4:Z4,增益属性!$A:$A,增益属性!$M:$M))} -> 0.2
A5: 护甲 | B5: 智识 | C5: =(VLOOKUP($A$2,干员属性!$A:$AG,5,FALSE)+IF(B5=B2,VLOOKUP($A$4,武器属性!$A:$AB,3,FALSE),0)+IF(B5=C2,VLOOKUP($A$4,武器属性!$A:$AB,4,FALSE),0)+VLOOKUP($A$4,武器属性!$A:$AB,7,FALSE)+VLOOKUP($A$6,护甲属性!$A:$Z,5,FALSE)+VLOOKUP($A$8,护手属性!$A:$Z,5,FALSE)+VLOOKUP($A$10,配件属性!$A:$Z,5,FALSE)+VLOOKUP($A$12,配件属性!$A:$Z,5,FALSE)+VLOOKUP($A$14,套装属性!$A:$Z,5,FALSE)+VLOOKUP($A$16,食物属性!$A:$Z,5,FALSE))*(1+(IF(B2="智识",C24,0)+IF(C2="智识",C25,0))) -> 90.9 | G5: =AA5*AC5*(1+AF5)*(1+AG5)*(1+AH5)*(1+AI5)*(1+AJ5)*(1+AK5)*(1-$D$2+AL5)*(1+AM5)*(1+AN5)*0.5*AE5*J5 -> 0 | H5: =AA5*AC5*(1+AF5)*(1+AG5)*(1+AH5)*(1+AI5)*(1+AJ5)*(1+AK5)*(1-$D$2+AL5)*(1+AM5)*(1+AN5)*0.5*J5 -> 0 | I5: =AA5*AC5*(1+AF5)*(1+AG5)*(1+AH5)*(1+AI5)*(1+AJ5)*(1+AK5)*(1-$D$2+AL5)*(1+AM5)*(1+AN5)*0.5*(AE5*AD5+(1-AD5))*J5 -> 0 | J5: 1 | K5: N/a | L5: N/a | M5: N/a | N5: N/a | O5: N/a | P5: N/a | Q5: N/a | R5: N/a | S5: N/a | T5: N/a | U5: N/a | V5: N/a | W5: N/a | X5: N/a | Y5: N/a | Z5: N/a | AA5: =VLOOKUP(K5,技能属性!$A:$AB,2,FALSE) -> 0 | AB5: {=$C$8+SUM(_xlfn.XLOOKUP(L5:Z5,增益属性!$A:$A,增益属性!$N:$N,0))} -> 0.47 | AC5: {=($C$7*(1+AB5)+$C$27)*(1+(INT((VLOOKUP(VLOOKUP($A$2,干员属性!$A:$AB,24,FALSE),$B$3:$C$6,2,FALSE)/(1+$C$24)*(1+$C$24+SUM(_xlfn.XLOOKUP(L5:Z5,增益属性!$A:$A,增益属性!$O:$O,0)))))*0.5+INT(VLOOKUP(VLOOKUP($A$2,干员属性!$A:$AB,25,FALSE),$B$3:$C$6,2,FALSE)*(1+SUM(_xlfn.XLOOKUP(L5:Z5,增益属性!$A:$A,增益属性!$O:$O,0))))*0.2+(INT(IFERROR(VLOOKUP(VLOOKUP($A$2,干员属性!$A:$AB,26,FALSE),$B$3:$C$6,2,FALSE),0)/(1+$C$25)*(1+$C$25+SUM(_xlfn.XLOOKUP(L5:Z5,增益属性!$A:$A,增益属性!$O:$O,0))))+INT(IFERROR(VLOOKUP(VLOOKUP($A$2,干员属性!$A:$AB,27,FALSE),$B$3:$C$6,2,FALSE),0)*(1+SUM(_xlfn.XLOOKUP(L5:Z5,增益属性!$A:$A,增益属性!$O:$O,0)))))*VLOOKUP($A$2,干员属性!$A:$AB,28,FALSE))/100)} -> 6896.898 | AD5: {=$C$10+VLOOKUP(K5,技能属性!$A:$Z,3,FALSE)+SUM(_xlfn.XLOOKUP(L5:Z5,增益属性!$A:$A,增益属性!$B:$B))} -> 0.16 | AE5: {=$C$11+VLOOKUP(K5,技能属性!$A:$AB,4,FALSE)+SUM(_xlfn.XLOOKUP(L5:Z5,增益属性!$A:$A,增益属性!$C:$C))} -> 1.5 | AF5: {=VLOOKUP(VLOOKUP(K5,技能属性!$A:$Z,5,FALSE),$B$14:$C$18,2,FALSE)+SUM(_xlfn.XLOOKUP(L5:Z5,增益属性!$A:$A,增益属性!$D:$D))+SUM(_xlfn.XLOOKUP(L5:Z5,增益属性!$A:$A,增益属性!$E:$E))+IF(VLOOKUP(K5,技能属性!$A:$Z,6,FALSE)="无",0,VLOOKUP(VLOOKUP(K5,技能属性!$A:$Z,6,FALSE),$B$20:$C$23,2,FALSE))+IF(VLOOKUP(K5,技能属性!$A:$Z,7,FALSE)=0,0,$C$19)} -> 0.7045 | AG5: {=IF(VLOOKUP(K5,技能属性!$A:$Z,8,FALSE)=0,0,$C$12+SUM(_xlfn.XLOOKUP(L5:Z5,增益属性!$A:$A,增益属性!$F:$F)))} -> 0 | AH5: {=VLOOKUP(K5,技能属性!$A:$Z,9,FALSE)+SUM(_xlfn.XLOOKUP(L5:Z5,增益属性!$A:$A,增益属性!$G:$G))} -> 0 | AI5: {=VLOOKUP(K5,技能属性!$A:$Z,10,FALSE)+SUM(_xlfn.XLOOKUP(L5:Z5,增益属性!$A:$A,增益属性!$H:$H))} -> 0 | AJ5: {=VLOOKUP(K5,技能属性!$A:$Z,11,FALSE)+SUM(_xlfn.XLOOKUP(L5:Z5,增益属性!$A:$A,增益属性!$I:$I))} -> 0 | AK5: {=VLOOKUP(K5,技能属性!$A:$Z,12,FALSE)+SUM(_xlfn.XLOOKUP(L5:Z5,增益属性!$A:$A,增益属性!$J:$J))} -> 0 | AL5: {=VLOOKUP(K5,技能属性!$A:$Z,13,FALSE)+SUM(_xlfn.XLOOKUP(L5:Z5,增益属性!$A:$A,增益属性!$K:$K))} -> 0 | AM5: {=VLOOKUP(K5,技能属性!$A:$Z,14,FALSE)+SUM(_xlfn.XLOOKUP(L5:Z5,增益属性!$A:$A,增益属性!$L:$L))} -> 0 | AN5: {=VLOOKUP(K5,技能属性!$A:$Z,15,FALSE)+SUM(_xlfn.XLOOKUP(L5:Z5,增益属性!$A:$A,增益属性!$M:$M))} -> 0
A6: 旧锋装甲3锻 | B6: 意志 | C6: =(VLOOKUP($A$2,干员属性!$A:$AG,6,FALSE)+IF(B6=B2,VLOOKUP($A$4,武器属性!$A:$AB,3,FALSE),0)+IF(B6=C2,VLOOKUP($A$4,武器属性!$A:$AB,4,FALSE),0)+VLOOKUP($A$4,武器属性!$A:$AB,8,FALSE)+VLOOKUP($A$6,护甲属性!$A:$Z,6,FALSE)+VLOOKUP($A$8,护手属性!$A:$Z,6,FALSE)+VLOOKUP($A$10,配件属性!$A:$Z,6,FALSE)+VLOOKUP($A$12,配件属性!$A:$Z,6,FALSE)+VLOOKUP($A$14,套装属性!$A:$Z,6,FALSE)+VLOOKUP($A$16,食物属性!$A:$Z,6,FALSE))*(1+(IF(B2="意志",C24,0)+IF(C2="意志",C25,0))) -> 276.25 | D6: 总伤 | E6: =SUM(I2:I1000) -> 432586.9 | G6: =AA6*AC6*(1+AF6)*(1+AG6)*(1+AH6)*(1+AI6)*(1+AJ6)*(1+AK6)*(1-$D$2+AL6)*(1+AM6)*(1+AN6)*0.5*AE6*J6 -> 30720.831 | H6: =AA6*AC6*(1+AF6)*(1+AG6)*(1+AH6)*(1+AI6)*(1+AJ6)*(1+AK6)*(1-$D$2+AL6)*(1+AM6)*(1+AN6)*0.5*J6 -> 20480.554 | I6: =AA6*AC6*(1+AF6)*(1+AG6)*(1+AH6)*(1+AI6)*(1+AJ6)*(1+AK6)*(1-$D$2+AL6)*(1+AM6)*(1+AN6)*0.5*(AE6*AD6+(1-AD6))*J6 -> 22118.998 | J6: 1 | K6: 弭弗连携 | L6: 旧锋3层翻倍 | M6: 弭弗连携脆弱0潜 | N6: 弭弗专武+强度0潜 | O6: 弭弗专武+物伤3层0潜 | P6: N/a | Q6: N/a | R6: N/a | S6: N/a | T6: N/a | U6: N/a | V6: N/a | W6: N/a | X6: N/a | Y6: N/a | Z6: N/a | AA6: =VLOOKUP(K6,技能属性!$A:$AB,2,FALSE) -> 2.5 | AB6: {=$C$8+SUM(_xlfn.XLOOKUP(L6:Z6,增益属性!$A:$A,增益属性!$N:$N,0))} -> 0.47 | AC6: {=($C$7*(1+AB6)+$C$27)*(1+(INT((VLOOKUP(VLOOKUP($A$2,干员属性!$A:$AB,24,FALSE),$B$3:$C$6,2,FALSE)/(1+$C$24)*(1+$C$24+SUM(_xlfn.XLOOKUP(L6:Z6,增益属性!$A:$A,增益属性!$O:$O,0)))))*0.5+INT(VLOOKUP(VLOOKUP($A$2,干员属性!$A:$AB,25,FALSE),$B$3:$C$6,2,FALSE)*(1+SUM(_xlfn.XLOOKUP(L6:Z6,增益属性!$A:$A,增益属性!$O:$O,0))))*0.2+(INT(IFERROR(VLOOKUP(VLOOKUP($A$2,干员属性!$A:$AB,26,FALSE),$B$3:$C$6,2,FALSE),0)/(1+$C$25)*(1+$C$25+SUM(_xlfn.XLOOKUP(L6:Z6,增益属性!$A:$A,增益属性!$O:$O,0))))+INT(IFERROR(VLOOKUP(VLOOKUP($A$2,干员属性!$A:$AB,27,FALSE),$B$3:$C$6,2,FALSE),0)*(1+SUM(_xlfn.XLOOKUP(L6:Z6,增益属性!$A:$A,增益属性!$O:$O,0)))))*VLOOKUP($A$2,干员属性!$A:$AB,28,FALSE))/100)} -> 6896.898 | AD6: {=$C$10+VLOOKUP(K6,技能属性!$A:$Z,3,FALSE)+SUM(_xlfn.XLOOKUP(L6:Z6,增益属性!$A:$A,增益属性!$B:$B))} -> 0.16 | AE6: {=$C$11+VLOOKUP(K6,技能属性!$A:$AB,4,FALSE)+SUM(_xlfn.XLOOKUP(L6:Z6,增益属性!$A:$A,增益属性!$C:$C))} -> 1.5 | AF6: {=VLOOKUP(VLOOKUP(K6,技能属性!$A:$Z,5,FALSE),$B$14:$C$18,2,FALSE)+SUM(_xlfn.XLOOKUP(L6:Z6,增益属性!$A:$A,增益属性!$D:$D))+SUM(_xlfn.XLOOKUP(L6:Z6,增益属性!$A:$A,增益属性!$E:$E))+IF(VLOOKUP(K6,技能属性!$A:$Z,6,FALSE)="无",0,VLOOKUP(VLOOKUP(K6,技能属性!$A:$Z,6,FALSE),$B$20:$C$23,2,FALSE))+IF(VLOOKUP(K6,技能属性!$A:$Z,7,FALSE)=0,0,$C$19)} -> 1.2625 | AG6: {=IF(VLOOKUP(K6,技能属性!$A:$Z,8,FALSE)=0,0,$C$12+SUM(_xlfn.XLOOKUP(L6:Z6,增益属性!$A:$A,增益属性!$F:$F)))} -> 0 | AH6: {=VLOOKUP(K6,技能属性!$A:$Z,9,FALSE)+SUM(_xlfn.XLOOKUP(L6:Z6,增益属性!$A:$A,增益属性!$G:$G))} -> 0 | AI6: {=VLOOKUP(K6,技能属性!$A:$Z,10,FALSE)+SUM(_xlfn.XLOOKUP(L6:Z6,增益属性!$A:$A,增益属性!$H:$H))} -> 0.05 | AJ6: {=VLOOKUP(K6,技能属性!$A:$Z,11,FALSE)+SUM(_xlfn.XLOOKUP(L6:Z6,增益属性!$A:$A,增益属性!$I:$I))} -> 0 | AK6: {=VLOOKUP(K6,技能属性!$A:$Z,12,FALSE)+SUM(_xlfn.XLOOKUP(L6:Z6,增益属性!$A:$A,增益属性!$J:$J))} -> 0 | AL6: {=VLOOKUP(K6,技能属性!$A:$Z,13,FALSE)+SUM(_xlfn.XLOOKUP(L6:Z6,增益属性!$A:$A,增益属性!$K:$K))} -> 0 | AM6: {=VLOOKUP(K6,技能属性!$A:$Z,14,FALSE)+SUM(_xlfn.XLOOKUP(L6:Z6,增益属性!$A:$A,增益属性!$L:$L))} -> 0 | AN6: {=VLOOKUP(K6,技能属性!$A:$Z,15,FALSE)+SUM(_xlfn.XLOOKUP(L6:Z6,增益属性!$A:$A,增益属性!$M:$M))} -> 0
A7: 护手 | B7: 基础攻击 | C7: =VLOOKUP($A$2,干员属性!$A:$AG,2,FALSE)+VLOOKUP($A$4,武器属性!$A:$AB,2,FALSE)+VLOOKUP($A$6,护甲属性!$A:$Z,2,FALSE)+VLOOKUP($A$8,护手属性!$A:$Z,2,FALSE)+VLOOKUP($A$10,配件属性!$A:$Z,2,FALSE)+VLOOKUP($A$12,配件属性!$A:$Z,2,FALSE)+VLOOKUP($A$14,套装属性!$A:$Z,2,FALSE) -> 825 | G7: =AA7*AC7*(1+AF7)*(1+AG7)*(1+AH7)*(1+AI7)*(1+AJ7)*(1+AK7)*(1-$D$2+AL7)*(1+AM7)*(1+AN7)*0.5*AE7*J7 -> 86018.327 | H7: =AA7*AC7*(1+AF7)*(1+AG7)*(1+AH7)*(1+AI7)*(1+AJ7)*(1+AK7)*(1-$D$2+AL7)*(1+AM7)*(1+AN7)*0.5*J7 -> 57345.552 | I7: =AA7*AC7*(1+AF7)*(1+AG7)*(1+AH7)*(1+AI7)*(1+AJ7)*(1+AK7)*(1-$D$2+AL7)*(1+AM7)*(1+AN7)*0.5*(AE7*AD7+(1-AD7))*J7 -> 61933.196 | J7: 1 | K7: 弭弗大招 | L7: 旧锋3层翻倍 | M7: 弭弗连携脆弱0潜 | N7: 弭弗专武+强度0潜 | O7: 弭弗专武+物伤3层0潜 | P7: N/a | Q7: N/a | R7: N/a | S7: N/a | T7: N/a | U7: N/a | V7: N/a | W7: N/a | X7: N/a | Y7: N/a | Z7: N/a | AA7: =VLOOKUP(K7,技能属性!$A:$AB,2,FALSE) -> 7 | AB7: {=$C$8+SUM(_xlfn.XLOOKUP(L7:Z7,增益属性!$A:$A,增益属性!$N:$N,0))} -> 0.47 | AC7: {=($C$7*(1+AB7)+$C$27)*(1+(INT((VLOOKUP(VLOOKUP($A$2,干员属性!$A:$AB,24,FALSE),$B$3:$C$6,2,FALSE)/(1+$C$24)*(1+$C$24+SUM(_xlfn.XLOOKUP(L7:Z7,增益属性!$A:$A,增益属性!$O:$O,0)))))*0.5+INT(VLOOKUP(VLOOKUP($A$2,干员属性!$A:$AB,25,FALSE),$B$3:$C$6,2,FALSE)*(1+SUM(_xlfn.XLOOKUP(L7:Z7,增益属性!$A:$A,增益属性!$O:$O,0))))*0.2+(INT(IFERROR(VLOOKUP(VLOOKUP($A$2,干员属性!$A:$AB,26,FALSE),$B$3:$C$6,2,FALSE),0)/(1+$C$25)*(1+$C$25+SUM(_xlfn.XLOOKUP(L7:Z7,增益属性!$A:$A,增益属性!$O:$O,0))))+INT(IFERROR(VLOOKUP(VLOOKUP($A$2,干员属性!$A:$AB,27,FALSE),$B$3:$C$6,2,FALSE),0)*(1+SUM(_xlfn.XLOOKUP(L7:Z7,增益属性!$A:$A,增益属性!$O:$O,0)))))*VLOOKUP($A$2,干员属性!$A:$AB,28,FALSE))/100)} -> 6896.898 | AD7: {=$C$10+VLOOKUP(K7,技能属性!$A:$Z,3,FALSE)+SUM(_xlfn.XLOOKUP(L7:Z7,增益属性!$A:$A,增益属性!$B:$B))} -> 0.16 | AE7: {=$C$11+VLOOKUP(K7,技能属性!$A:$AB,4,FALSE)+SUM(_xlfn.XLOOKUP(L7:Z7,增益属性!$A:$A,增益属性!$C:$C))} -> 1.5 | AF7: {=VLOOKUP(VLOOKUP(K7,技能属性!$A:$Z,5,FALSE),$B$14:$C$18,2,FALSE)+SUM(_xlfn.XLOOKUP(L7:Z7,增益属性!$A:$A,增益属性!$D:$D))+SUM(_xlfn.XLOOKUP(L7:Z7,增益属性!$A:$A,增益属性!$E:$E))+IF(VLOOKUP(K7,技能属性!$A:$Z,6,FALSE)="无",0,VLOOKUP(VLOOKUP(K7,技能属性!$A:$Z,6,FALSE),$B$20:$C$23,2,FALSE))+IF(VLOOKUP(K7,技能属性!$A:$Z,7,FALSE)=0,0,$C$19)} -> 1.2625 | AG7: {=IF(VLOOKUP(K7,技能属性!$A:$Z,8,FALSE)=0,0,$C$12+SUM(_xlfn.XLOOKUP(L7:Z7,增益属性!$A:$A,增益属性!$F:$F)))} -> 0 | AH7: {=VLOOKUP(K7,技能属性!$A:$Z,9,FALSE)+SUM(_xlfn.XLOOKUP(L7:Z7,增益属性!$A:$A,增益属性!$G:$G))} -> 0 | AI7: {=VLOOKUP(K7,技能属性!$A:$Z,10,FALSE)+SUM(_xlfn.XLOOKUP(L7:Z7,增益属性!$A:$A,增益属性!$H:$H))} -> 0.05 | AJ7: {=VLOOKUP(K7,技能属性!$A:$Z,11,FALSE)+SUM(_xlfn.XLOOKUP(L7:Z7,增益属性!$A:$A,增益属性!$I:$I))} -> 0 | AK7: {=VLOOKUP(K7,技能属性!$A:$Z,12,FALSE)+SUM(_xlfn.XLOOKUP(L7:Z7,增益属性!$A:$A,增益属性!$J:$J))} -> 0 | AL7: {=VLOOKUP(K7,技能属性!$A:$Z,13,FALSE)+SUM(_xlfn.XLOOKUP(L7:Z7,增益属性!$A:$A,增益属性!$K:$K))} -> 0 | AM7: {=VLOOKUP(K7,技能属性!$A:$Z,14,FALSE)+SUM(_xlfn.XLOOKUP(L7:Z7,增益属性!$A:$A,增益属性!$L:$L))} -> 0 | AN7: {=VLOOKUP(K7,技能属性!$A:$Z,15,FALSE)+SUM(_xlfn.XLOOKUP(L7:Z7,增益属性!$A:$A,增益属性!$M:$M))} -> 0
A8: 旧锋手甲3锻 | B8: 攻击力加成 | C8: =VLOOKUP($A$2,干员属性!$A:$AG,21,FALSE)+VLOOKUP($A$4,武器属性!$A:$AB,23,FALSE)+VLOOKUP($A$6,护甲属性!$A:$Z,21,FALSE)+VLOOKUP($A$8,护手属性!$A:$Z,21,FALSE)+VLOOKUP($A$10,配件属性!$A:$Z,21,FALSE)+VLOOKUP($A$12,配件属性!$A:$Z,21,FALSE)+VLOOKUP($A$14,套装属性!$A:$Z,21,FALSE)+VLOOKUP($A$16,食物属性!$A:$Z,21,FALSE) -> 0.47 | G8: =AA8*AC8*(1+AF8)*(1+AG8)*(1+AH8)*(1+AI8)*(1+AJ8)*(1+AK8)*(1-$D$2+AL8)*(1+AM8)*(1+AN8)*0.5*AE8*J8 -> 18093.943 | H8: =AA8*AC8*(1+AF8)*(1+AG8)*(1+AH8)*(1+AI8)*(1+AJ8)*(1+AK8)*(1-$D$2+AL8)*(1+AM8)*(1+AN8)*0.5*J8 -> 12062.628 | I8: =AA8*AC8*(1+AF8)*(1+AG8)*(1+AH8)*(1+AI8)*(1+AJ8)*(1+AK8)*(1-$D$2+AL8)*(1+AM8)*(1+AN8)*0.5*(AE8*AD8+(1-AD8))*J8 -> 13027.639 | J8: 1 | K8: 倒地/击飞 | L8: 旧锋3层翻倍 | M8: 弭弗连携脆弱0潜 | N8: 弭弗专武+强度0潜 | O8: 弭弗专武+物伤3层0潜 | P8: N/a | Q8: N/a | R8: N/a | S8: N/a | T8: N/a | U8: N/a | V8: N/a | W8: N/a | X8: N/a | Y8: N/a | Z8: N/a | AA8: =VLOOKUP(K8,技能属性!$A:$AB,2,FALSE) -> 1.2 | AB8: {=$C$8+SUM(_xlfn.XLOOKUP(L8:Z8,增益属性!$A:$A,增益属性!$N:$N,0))} -> 0.47 | AC8: {=($C$7*(1+AB8)+$C$27)*(1+(INT((VLOOKUP(VLOOKUP($A$2,干员属性!$A:$AB,24,FALSE),$B$3:$C$6,2,FALSE)/(1+$C$24)*(1+$C$24+SUM(_xlfn.XLOOKUP(L8:Z8,增益属性!$A:$A,增益属性!$O:$O,0)))))*0.5+INT(VLOOKUP(VLOOKUP($A$2,干员属性!$A:$AB,25,FALSE),$B$3:$C$6,2,FALSE)*(1+SUM(_xlfn.XLOOKUP(L8:Z8,增益属性!$A:$A,增益属性!$O:$O,0))))*0.2+(INT(IFERROR(VLOOKUP(VLOOKUP($A$2,干员属性!$A:$AB,26,FALSE),$B$3:$C$6,2,FALSE),0)/(1+$C$25)*(1+$C$25+SUM(_xlfn.XLOOKUP(L8:Z8,增益属性!$A:$A,增益属性!$O:$O,0))))+INT(IFERROR(VLOOKUP(VLOOKUP($A$2,干员属性!$A:$AB,27,FALSE),$B$3:$C$6,2,FALSE),0)*(1+SUM(_xlfn.XLOOKUP(L8:Z8,增益属性!$A:$A,增益属性!$O:$O,0)))))*VLOOKUP($A$2,干员属性!$A:$AB,28,FALSE))/100)} -> 6896.898 | AD8: {=$C$10+VLOOKUP(K8,技能属性!$A:$Z,3,FALSE)+SUM(_xlfn.XLOOKUP(L8:Z8,增益属性!$A:$A,增益属性!$B:$B))} -> 0.16 | AE8: {=$C$11+VLOOKUP(K8,技能属性!$A:$AB,4,FALSE)+SUM(_xlfn.XLOOKUP(L8:Z8,增益属性!$A:$A,增益属性!$C:$C))} -> 1.5 | AF8: {=VLOOKUP(VLOOKUP(K8,技能属性!$A:$Z,5,FALSE),$B$14:$C$18,2,FALSE)+SUM(_xlfn.XLOOKUP(L8:Z8,增益属性!$A:$A,增益属性!$D:$D))+SUM(_xlfn.XLOOKUP(L8:Z8,增益属性!$A:$A,增益属性!$E:$E))+IF(VLOOKUP(K8,技能属性!$A:$Z,6,FALSE)="无",0,VLOOKUP(VLOOKUP(K8,技能属性!$A:$Z,6,FALSE),$B$20:$C$23,2,FALSE))+IF(VLOOKUP(K8,技能属性!$A:$Z,7,FALSE)=0,0,$C$19)} -> 1.2625 | AG8: {=IF(VLOOKUP(K8,技能属性!$A:$Z,8,FALSE)=0,0,$C$12+SUM(_xlfn.XLOOKUP(L8:Z8,增益属性!$A:$A,增益属性!$F:$F)))} -> 0 | AH8: {=VLOOKUP(K8,技能属性!$A:$Z,9,FALSE)+SUM(_xlfn.XLOOKUP(L8:Z8,增益属性!$A:$A,增益属性!$G:$G))} -> 0 | AI8: {=VLOOKUP(K8,技能属性!$A:$Z,10,FALSE)+SUM(_xlfn.XLOOKUP(L8:Z8,增益属性!$A:$A,增益属性!$H:$H))} -> 0.05 | AJ8: {=VLOOKUP(K8,技能属性!$A:$Z,11,FALSE)+SUM(_xlfn.XLOOKUP(L8:Z8,增益属性!$A:$A,增益属性!$I:$I))} -> 0 | AK8: {=VLOOKUP(K8,技能属性!$A:$Z,12,FALSE)+SUM(_xlfn.XLOOKUP(L8:Z8,增益属性!$A:$A,增益属性!$J:$J))} -> 0 | AL8: {=VLOOKUP(K8,技能属性!$A:$Z,13,FALSE)+SUM(_xlfn.XLOOKUP(L8:Z8,增益属性!$A:$A,增益属性!$K:$K))} -> 0 | AM8: {=VLOOKUP(K8,技能属性!$A:$Z,14,FALSE)+SUM(_xlfn.XLOOKUP(L8:Z8,增益属性!$A:$A,增益属性!$L:$L))} -> 0 | AN8: {=VLOOKUP(K8,技能属性!$A:$Z,15,FALSE)+SUM(_xlfn.XLOOKUP(L8:Z8,增益属性!$A:$A,增益属性!$M:$M))} -> 0.22704082
A9: 配件一 | B9: 能力值加成 | C9: =(INT(VLOOKUP(VLOOKUP($A$2,干员属性!$A:$AB,24,FALSE),$B$3:$C$6,2,FALSE))*0.5+INT(VLOOKUP(VLOOKUP($A$2,干员属性!$A:$AB,25,FALSE),$B$3:$C$6,2,FALSE))*0.2+(IFERROR(INT(VLOOKUP(VLOOKUP($A$2,干员属性!$A:$AB,26,FALSE),$B$3:$C$6,2,FALSE)),0)+IFERROR(INT(VLOOKUP(VLOOKUP($A$2,干员属性!$A:$AB,27,FALSE),$B$3:$C$6,2,FALSE)),0))*VLOOKUP($A$2,干员属性!$A:$AB,28,FALSE))/100 -> 3.952 | D9: DPS | E9: =E6/E4 -> 432586.9 | G9: =AA9*AC9*(1+AF9)*(1+AG9)*(1+AH9)*(1+AI9)*(1+AJ9)*(1+AK9)*(1-$D$2+AL9)*(1+AM9)*(1+AN9)*0.5*AE9*J9 -> 0 | H9: =AA9*AC9*(1+AF9)*(1+AG9)*(1+AH9)*(1+AI9)*(1+AJ9)*(1+AK9)*(1-$D$2+AL9)*(1+AM9)*(1+AN9)*0.5*J9 -> 0 | I9: =AA9*AC9*(1+AF9)*(1+AG9)*(1+AH9)*(1+AI9)*(1+AJ9)*(1+AK9)*(1-$D$2+AL9)*(1+AM9)*(1+AN9)*0.5*(AE9*AD9+(1-AD9))*J9 -> 0 | J9: 1 | K9: N/a | L9: N/a | M9: N/a | N9: N/a | O9: N/a | P9: N/a | Q9: N/a | R9: N/a | S9: N/a | T9: N/a | U9: N/a | V9: N/a | W9: N/a | X9: N/a | Y9: N/a | Z9: N/a | AA9: =VLOOKUP(K9,技能属性!$A:$AB,2,FALSE) -> 0 | AB9: {=$C$8+SUM(_xlfn.XLOOKUP(L9:Z9,增益属性!$A:$A,增益属性!$N:$N,0))} -> 0.47 | AC9: {=($C$7*(1+AB9)+$C$27)*(1+(INT((VLOOKUP(VLOOKUP($A$2,干员属性!$A:$AB,24,FALSE),$B$3:$C$6,2,FALSE)/(1+$C$24)*(1+$C$24+SUM(_xlfn.XLOOKUP(L9:Z9,增益属性!$A:$A,增益属性!$O:$O,0)))))*0.5+INT(VLOOKUP(VLOOKUP($A$2,干员属性!$A:$AB,25,FALSE),$B$3:$C$6,2,FALSE)*(1+SUM(_xlfn.XLOOKUP(L9:Z9,增益属性!$A:$A,增益属性!$O:$O,0))))*0.2+(INT(IFERROR(VLOOKUP(VLOOKUP($A$2,干员属性!$A:$AB,26,FALSE),$B$3:$C$6,2,FALSE),0)/(1+$C$25)*(1+$C$25+SUM(_xlfn.XLOOKUP(L9:Z9,增益属性!$A:$A,增益属性!$O:$O,0))))+INT(IFERROR(VLOOKUP(VLOOKUP($A$2,干员属性!$A:$AB,27,FALSE),$B$3:$C$6,2,FALSE),0)*(1+SUM(_xlfn.XLOOKUP(L9:Z9,增益属性!$A:$A,增益属性!$O:$O,0)))))*VLOOKUP($A$2,干员属性!$A:$AB,28,FALSE))/100)} -> 6896.898 | AD9: {=$C$10+VLOOKUP(K9,技能属性!$A:$Z,3,FALSE)+SUM(_xlfn.XLOOKUP(L9:Z9,增益属性!$A:$A,增益属性!$B:$B))} -> 0.16 | AE9: {=$C$11+VLOOKUP(K9,技能属性!$A:$AB,4,FALSE)+SUM(_xlfn.XLOOKUP(L9:Z9,增益属性!$A:$A,增益属性!$C:$C))} -> 1.5 | AF9: {=VLOOKUP(VLOOKUP(K9,技能属性!$A:$Z,5,FALSE),$B$14:$C$18,2,FALSE)+SUM(_xlfn.XLOOKUP(L9:Z9,增益属性!$A:$A,增益属性!$D:$D))+SUM(_xlfn.XLOOKUP(L9:Z9,增益属性!$A:$A,增益属性!$E:$E))+IF(VLOOKUP(K9,技能属性!$A:$Z,6,FALSE)="无",0,VLOOKUP(VLOOKUP(K9,技能属性!$A:$Z,6,FALSE),$B$20:$C$23,2,FALSE))+IF(VLOOKUP(K9,技能属性!$A:$Z,7,FALSE)=0,0,$C$19)} -> 0.7045 | AG9: {=IF(VLOOKUP(K9,技能属性!$A:$Z,8,FALSE)=0,0,$C$12+SUM(_xlfn.XLOOKUP(L9:Z9,增益属性!$A:$A,增益属性!$F:$F)))} -> 0 | AH9: {=VLOOKUP(K9,技能属性!$A:$Z,9,FALSE)+SUM(_xlfn.XLOOKUP(L9:Z9,增益属性!$A:$A,增益属性!$G:$G))} -> 0 | AI9: {=VLOOKUP(K9,技能属性!$A:$Z,10,FALSE)+SUM(_xlfn.XLOOKUP(L9:Z9,增益属性!$A:$A,增益属性!$H:$H))} -> 0 | AJ9: {=VLOOKUP(K9,技能属性!$A:$Z,11,FALSE)+SUM(_xlfn.XLOOKUP(L9:Z9,增益属性!$A:$A,增益属性!$I:$I))} -> 0 | AK9: {=VLOOKUP(K9,技能属性!$A:$Z,12,FALSE)+SUM(_xlfn.XLOOKUP(L9:Z9,增益属性!$A:$A,增益属性!$J:$J))} -> 0 | AL9: {=VLOOKUP(K9,技能属性!$A:$Z,13,FALSE)+SUM(_xlfn.XLOOKUP(L9:Z9,增益属性!$A:$A,增益属性!$K:$K))} -> 0 | AM9: {=VLOOKUP(K9,技能属性!$A:$Z,14,FALSE)+SUM(_xlfn.XLOOKUP(L9:Z9,增益属性!$A:$A,增益属性!$L:$L))} -> 0 | AN9: {=VLOOKUP(K9,技能属性!$A:$Z,15,FALSE)+SUM(_xlfn.XLOOKUP(L9:Z9,增益属性!$A:$A,增益属性!$M:$M))} -> 0
A10: 旧锋刺刃3锻 | B10: 暴击 | C10: =VLOOKUP($A$2,干员属性!$A:$AG,7,FALSE)+VLOOKUP($A$4,武器属性!$A:$AB,9,FALSE)+VLOOKUP($A$6,护甲属性!$A:$Z,7,FALSE)+VLOOKUP($A$8,护手属性!$A:$Z,7,FALSE)+VLOOKUP($A$10,配件属性!$A:$Z,7,FALSE)+VLOOKUP($A$12,配件属性!$A:$Z,7,FALSE)+VLOOKUP($A$14,套装属性!$A:$Z,7,FALSE)+VLOOKUP($A$16,食物属性!$A:$Z,7,FALSE) -> 0.16 | G10: =AA10*AC10*(1+AF10)*(1+AG10)*(1+AH10)*(1+AI10)*(1+AJ10)*(1+AK10)*(1-$D$2+AL10)*(1+AM10)*(1+AN10)*0.5*AE10*J10 -> 0 | H10: =AA10*AC10*(1+AF10)*(1+AG10)*(1+AH10)*(1+AI10)*(1+AJ10)*(1+AK10)*(1-$D$2+AL10)*(1+AM10)*(1+AN10)*0.5*J10 -> 0 | I10: =AA10*AC10*(1+AF10)*(1+AG10)*(1+AH10)*(1+AI10)*(1+AJ10)*(1+AK10)*(1-$D$2+AL10)*(1+AM10)*(1+AN10)*0.5*(AE10*AD10+(1-AD10))*J10 -> 0 | J10: 1 | K10: N/a | L10: N/a | M10: N/a | N10: N/a | O10: N/a | P10: N/a | Q10: N/a | R10: N/a | S10: N/a | T10: N/a | U10: N/a | V10: N/a | W10: N/a | X10: N/a | Y10: N/a | Z10: N/a | AA10: =VLOOKUP(K10,技能属性!$A:$AB,2,FALSE) -> 0 | AB10: {=$C$8+SUM(_xlfn.XLOOKUP(L10:Z10,增益属性!$A:$A,增益属性!$N:$N,0))} -> 0.47 | AC10: {=($C$7*(1+AB10)+$C$27)*(1+(INT((VLOOKUP(VLOOKUP($A$2,干员属性!$A:$AB,24,FALSE),$B$3:$C$6,2,FALSE)/(1+$C$24)*(1+$C$24+SUM(_xlfn.XLOOKUP(L10:Z10,增益属性!$A:$A,增益属性!$O:$O,0)))))*0.5+INT(VLOOKUP(VLOOKUP($A$2,干员属性!$A:$AB,25,FALSE),$B$3:$C$6,2,FALSE)*(1+SUM(_xlfn.XLOOKUP(L10:Z10,增益属性!$A:$A,增益属性!$O:$O,0))))*0.2+(INT(IFERROR(VLOOKUP(VLOOKUP($A$2,干员属性!$A:$AB,26,FALSE),$B$3:$C$6,2,FALSE),0)/(1+$C$25)*(1+$C$25+SUM(_xlfn.XLOOKUP(L10:Z10,增益属性!$A:$A,增益属性!$O:$O,0))))+INT(IFERROR(VLOOKUP(VLOOKUP($A$2,干员属性!$A:$AB,27,FALSE),$B$3:$C$6,2,FALSE),0)*(1+SUM(_xlfn.XLOOKUP(L10:Z10,增益属性!$A:$A,增益属性!$O:$O,0)))))*VLOOKUP($A$2,干员属性!$A:$AB,28,FALSE))/100)} -> 6896.898 | AD10: {=$C$10+VLOOKUP(K10,技能属性!$A:$Z,3,FALSE)+SUM(_xlfn.XLOOKUP(L10:Z10,增益属性!$A:$A,增益属性!$B:$B))} -> 0.16 | AE10: {=$C$11+VLOOKUP(K10,技能属性!$A:$AB,4,FALSE)+SUM(_xlfn.XLOOKUP(L10:Z10,增益属性!$A:$A,增益属性!$C:$C))} -> 1.5 | AF10: {=VLOOKUP(VLOOKUP(K10,技能属性!$A:$Z,5,FALSE),$B$14:$C$18,2,FALSE)+SUM(_xlfn.XLOOKUP(L10:Z10,增益属性!$A:$A,增益属性!$D:$D))+SUM(_xlfn.XLOOKUP(L10:Z10,增益属性!$A:$A,增益属性!$E:$E))+IF(VLOOKUP(K10,技能属性!$A:$Z,6,FALSE)="无",0,VLOOKUP(VLOOKUP(K10,技能属性!$A:$Z,6,FALSE),$B$20:$C$23,2,FALSE))+IF(VLOOKUP(K10,技能属性!$A:$Z,7,FALSE)=0,0,$C$19)} -> 0.7045 | AG10: {=IF(VLOOKUP(K10,技能属性!$A:$Z,8,FALSE)=0,0,$C$12+SUM(_xlfn.XLOOKUP(L10:Z10,增益属性!$A:$A,增益属性!$F:$F)))} -> 0 | AH10: {=VLOOKUP(K10,技能属性!$A:$Z,9,FALSE)+SUM(_xlfn.XLOOKUP(L10:Z10,增益属性!$A:$A,增益属性!$G:$G))} -> 0 | AI10: {=VLOOKUP(K10,技能属性!$A:$Z,10,FALSE)+SUM(_xlfn.XLOOKUP(L10:Z10,增益属性!$A:$A,增益属性!$H:$H))} -> 0 | AJ10: {=VLOOKUP(K10,技能属性!$A:$Z,11,FALSE)+SUM(_xlfn.XLOOKUP(L10:Z10,增益属性!$A:$A,增益属性!$I:$I))} -> 0 | AK10: {=VLOOKUP(K10,技能属性!$A:$Z,12,FALSE)+SUM(_xlfn.XLOOKUP(L10:Z10,增益属性!$A:$A,增益属性!$J:$J))} -> 0 | AL10: {=VLOOKUP(K10,技能属性!$A:$Z,13,FALSE)+SUM(_xlfn.XLOOKUP(L10:Z10,增益属性!$A:$A,增益属性!$K:$K))} -> 0 | AM10: {=VLOOKUP(K10,技能属性!$A:$Z,14,FALSE)+SUM(_xlfn.XLOOKUP(L10:Z10,增益属性!$A:$A,增益属性!$L:$L))} -> 0 | AN10: {=VLOOKUP(K10,技能属性!$A:$Z,15,FALSE)+SUM(_xlfn.XLOOKUP(L10:Z10,增益属性!$A:$A,增益属性!$M:$M))} -> 0
A11: 配件二 | B11: 暴击伤害 | C11: =VLOOKUP($A$2,干员属性!$A:$AG,8,FALSE)+VLOOKUP($A$4,武器属性!$A:$AB,10,FALSE)+VLOOKUP($A$6,护甲属性!$A:$Z,8,FALSE)+VLOOKUP($A$8,护手属性!$A:$Z,8,FALSE)+VLOOKUP($A$10,配件属性!$A:$Z,8,FALSE)+VLOOKUP($A$12,配件属性!$A:$Z,8,FALSE)+VLOOKUP($A$14,套装属性!$A:$Z,8,FALSE)+VLOOKUP($A$16,食物属性!$A:$Z,8,FALSE) -> 1.5 | G11: =AA11*AC11*(1+AF11)*(1+AG11)*(1+AH11)*(1+AI11)*(1+AJ11)*(1+AK11)*(1-$D$2+AL11)*(1+AM11)*(1+AN11)*0.5*AE11*J11 -> 0 | H11: =AA11*AC11*(1+AF11)*(1+AG11)*(1+AH11)*(1+AI11)*(1+AJ11)*(1+AK11)*(1-$D$2+AL11)*(1+AM11)*(1+AN11)*0.5*J11 -> 0 | I11: =AA11*AC11*(1+AF11)*(1+AG11)*(1+AH11)*(1+AI11)*(1+AJ11)*(1+AK11)*(1-$D$2+AL11)*(1+AM11)*(1+AN11)*0.5*(AE11*AD11+(1-AD11))*J11 -> 0 | J11: 1 | K11: N/a | L11: N/a | M11: N/a | N11: N/a | O11: N/a | P11: N/a | Q11: N/a | R11: N/a | S11: N/a | T11: N/a | U11: N/a | V11: N/a | W11: N/a | X11: N/a | Y11: N/a | Z11: N/a | AA11: =VLOOKUP(K11,技能属性!$A:$AB,2,FALSE) -> 0 | AB11: {=$C$8+SUM(_xlfn.XLOOKUP(L11:Z11,增益属性!$A:$A,增益属性!$N:$N,0))} -> 0.47 | AC11: {=($C$7*(1+AB11)+$C$27)*(1+(INT((VLOOKUP(VLOOKUP($A$2,干员属性!$A:$AB,24,FALSE),$B$3:$C$6,2,FALSE)/(1+$C$24)*(1+$C$24+SUM(_xlfn.XLOOKUP(L11:Z11,增益属性!$A:$A,增益属性!$O:$O,0)))))*0.5+INT(VLOOKUP(VLOOKUP($A$2,干员属性!$A:$AB,25,FALSE),$B$3:$C$6,2,FALSE)*(1+SUM(_xlfn.XLOOKUP(L11:Z11,增益属性!$A:$A,增益属性!$O:$O,0))))*0.2+(INT(IFERROR(VLOOKUP(VLOOKUP($A$2,干员属性!$A:$AB,26,FALSE),$B$3:$C$6,2,FALSE),0)/(1+$C$25)*(1+$C$25+SUM(_xlfn.XLOOKUP(L11:Z11,增益属性!$A:$A,增益属性!$O:$O,0))))+INT(IFERROR(VLOOKUP(VLOOKUP($A$2,干员属性!$A:$AB,27,FALSE),$B$3:$C$6,2,FALSE),0)*(1+SUM(_xlfn.XLOOKUP(L11:Z11,增益属性!$A:$A,增益属性!$O:$O,0)))))*VLOOKUP($A$2,干员属性!$A:$AB,28,FALSE))/100)} -> 6896.898 | AD11: {=$C$10+VLOOKUP(K11,技能属性!$A:$Z,3,FALSE)+SUM(_xlfn.XLOOKUP(L11:Z11,增益属性!$A:$A,增益属性!$B:$B))} -> 0.16 | AE11: {=$C$11+VLOOKUP(K11,技能属性!$A:$AB,4,FALSE)+SUM(_xlfn.XLOOKUP(L11:Z11,增益属性!$A:$A,增益属性!$C:$C))} -> 1.5 | AF11: {=VLOOKUP(VLOOKUP(K11,技能属性!$A:$Z,5,FALSE),$B$14:$C$18,2,FALSE)+SUM(_xlfn.XLOOKUP(L11:Z11,增益属性!$A:$A,增益属性!$D:$D))+SUM(_xlfn.XLOOKUP(L11:Z11,增益属性!$A:$A,增益属性!$E:$E))+IF(VLOOKUP(K11,技能属性!$A:$Z,6,FALSE)="无",0,VLOOKUP(VLOOKUP(K11,技能属性!$A:$Z,6,FALSE),$B$20:$C$23,2,FALSE))+IF(VLOOKUP(K11,技能属性!$A:$Z,7,FALSE)=0,0,$C$19)} -> 0.7045 | AG11: {=IF(VLOOKUP(K11,技能属性!$A:$Z,8,FALSE)=0,0,$C$12+SUM(_xlfn.XLOOKUP(L11:Z11,增益属性!$A:$A,增益属性!$F:$F)))} -> 0 | AH11: {=VLOOKUP(K11,技能属性!$A:$Z,9,FALSE)+SUM(_xlfn.XLOOKUP(L11:Z11,增益属性!$A:$A,增益属性!$G:$G))} -> 0 | AI11: {=VLOOKUP(K11,技能属性!$A:$Z,10,FALSE)+SUM(_xlfn.XLOOKUP(L11:Z11,增益属性!$A:$A,增益属性!$H:$H))} -> 0 | AJ11: {=VLOOKUP(K11,技能属性!$A:$Z,11,FALSE)+SUM(_xlfn.XLOOKUP(L11:Z11,增益属性!$A:$A,增益属性!$I:$I))} -> 0 | AK11: {=VLOOKUP(K11,技能属性!$A:$Z,12,FALSE)+SUM(_xlfn.XLOOKUP(L11:Z11,增益属性!$A:$A,增益属性!$J:$J))} -> 0 | AL11: {=VLOOKUP(K11,技能属性!$A:$Z,13,FALSE)+SUM(_xlfn.XLOOKUP(L11:Z11,增益属性!$A:$A,增益属性!$K:$K))} -> 0 | AM11: {=VLOOKUP(K11,技能属性!$A:$Z,14,FALSE)+SUM(_xlfn.XLOOKUP(L11:Z11,增益属性!$A:$A,增益属性!$L:$L))} -> 0 | AN11: {=VLOOKUP(K11,技能属性!$A:$Z,15,FALSE)+SUM(_xlfn.XLOOKUP(L11:Z11,增益属性!$A:$A,增益属性!$M:$M))} -> 0
A12: 点剑定位信标3锻 | B12: 源石技艺 | C12: =VLOOKUP($A$2,干员属性!$A:$AG,9,FALSE)+VLOOKUP($A$4,武器属性!$A:$AB,11,FALSE)+VLOOKUP($A$6,护甲属性!$A:$Z,9,FALSE)+VLOOKUP($A$8,护手属性!$A:$Z,9,FALSE)+VLOOKUP($A$10,配件属性!$A:$Z,9,FALSE)+VLOOKUP($A$12,配件属性!$A:$Z,9,FALSE)+VLOOKUP($A$14,套装属性!$A:$Z,9,FALSE)+VLOOKUP($A$16,食物属性!$A:$Z,9,FALSE) -> 0.9867 | G12: =AA12*AC12*(1+AF12)*(1+AG12)*(1+AH12)*(1+AI12)*(1+AJ12)*(1+AK12)*(1-$D$2+AL12)*(1+AM12)*(1+AN12)*0.5*AE12*J12 -> 0 | H12: =AA12*AC12*(1+AF12)*(1+AG12)*(1+AH12)*(1+AI12)*(1+AJ12)*(1+AK12)*(1-$D$2+AL12)*(1+AM12)*(1+AN12)*0.5*J12 -> 0 | I12: =AA12*AC12*(1+AF12)*(1+AG12)*(1+AH12)*(1+AI12)*(1+AJ12)*(1+AK12)*(1-$D$2+AL12)*(1+AM12)*(1+AN12)*0.5*(AE12*AD12+(1-AD12))*J12 -> 0 | J12: 1 | K12: N/a | L12: N/a | M12: N/a | N12: N/a | O12: N/a | P12: N/a | Q12: N/a | R12: N/a | S12: N/a | T12: N/a | U12: N/a | V12: N/a | W12: N/a | X12: N/a | Y12: N/a | Z12: N/a | AA12: =VLOOKUP(K12,技能属性!$A:$AB,2,FALSE) -> 0 | AB12: {=$C$8+SUM(_xlfn.XLOOKUP(L12:Z12,增益属性!$A:$A,增益属性!$N:$N,0))} -> 0.47 | AC12: {=($C$7*(1+AB12)+$C$27)*(1+(INT((VLOOKUP(VLOOKUP($A$2,干员属性!$A:$AB,24,FALSE),$B$3:$C$6,2,FALSE)/(1+$C$24)*(1+$C$24+SUM(_xlfn.XLOOKUP(L12:Z12,增益属性!$A:$A,增益属性!$O:$O,0)))))*0.5+INT(VLOOKUP(VLOOKUP($A$2,干员属性!$A:$AB,25,FALSE),$B$3:$C$6,2,FALSE)*(1+SUM(_xlfn.XLOOKUP(L12:Z12,增益属性!$A:$A,增益属性!$O:$O,0))))*0.2+(INT(IFERROR(VLOOKUP(VLOOKUP($A$2,干员属性!$A:$AB,26,FALSE),$B$3:$C$6,2,FALSE),0)/(1+$C$25)*(1+$C$25+SUM(_xlfn.XLOOKUP(L12:Z12,增益属性!$A:$A,增益属性!$O:$O,0))))+INT(IFERROR(VLOOKUP(VLOOKUP($A$2,干员属性!$A:$AB,27,FALSE),$B$3:$C$6,2,FALSE),0)*(1+SUM(_xlfn.XLOOKUP(L12:Z12,增益属性!$A:$A,增益属性!$O:$O,0)))))*VLOOKUP($A$2,干员属性!$A:$AB,28,FALSE))/100)} -> 6896.898 | AD12: {=$C$10+VLOOKUP(K12,技能属性!$A:$Z,3,FALSE)+SUM(_xlfn.XLOOKUP(L12:Z12,增益属性!$A:$A,增益属性!$B:$B))} -> 0.16 | AE12: {=$C$11+VLOOKUP(K12,技能属性!$A:$AB,4,FALSE)+SUM(_xlfn.XLOOKUP(L12:Z12,增益属性!$A:$A,增益属性!$C:$C))} -> 1.5 | AF12: {=VLOOKUP(VLOOKUP(K12,技能属性!$A:$Z,5,FALSE),$B$14:$C$18,2,FALSE)+SUM(_xlfn.XLOOKUP(L12:Z12,增益属性!$A:$A,增益属性!$D:$D))+SUM(_xlfn.XLOOKUP(L12:Z12,增益属性!$A:$A,增益属性!$E:$E))+IF(VLOOKUP(K12,技能属性!$A:$Z,6,FALSE)="无",0,VLOOKUP(VLOOKUP(K12,技能属性!$A:$Z,6,FALSE),$B$20:$C$23,2,FALSE))+IF(VLOOKUP(K12,技能属性!$A:$Z,7,FALSE)=0,0,$C$19)} -> 0.7045 | AG12: {=IF(VLOOKUP(K12,技能属性!$A:$Z,8,FALSE)=0,0,$C$12+SUM(_xlfn.XLOOKUP(L12:Z12,增益属性!$A:$A,增益属性!$F:$F)))} -> 0 | AH12: {=VLOOKUP(K12,技能属性!$A:$Z,9,FALSE)+SUM(_xlfn.XLOOKUP(L12:Z12,增益属性!$A:$A,增益属性!$G:$G))} -> 0 | AI12: {=VLOOKUP(K12,技能属性!$A:$Z,10,FALSE)+SUM(_xlfn.XLOOKUP(L12:Z12,增益属性!$A:$A,增益属性!$H:$H))} -> 0 | AJ12: {=VLOOKUP(K12,技能属性!$A:$Z,11,FALSE)+SUM(_xlfn.XLOOKUP(L12:Z12,增益属性!$A:$A,增益属性!$I:$I))} -> 0 | AK12: {=VLOOKUP(K12,技能属性!$A:$Z,12,FALSE)+SUM(_xlfn.XLOOKUP(L12:Z12,增益属性!$A:$A,增益属性!$J:$J))} -> 0 | AL12: {=VLOOKUP(K12,技能属性!$A:$Z,13,FALSE)+SUM(_xlfn.XLOOKUP(L12:Z12,增益属性!$A:$A,增益属性!$K:$K))} -> 0 | AM12: {=VLOOKUP(K12,技能属性!$A:$Z,14,FALSE)+SUM(_xlfn.XLOOKUP(L12:Z12,增益属性!$A:$A,增益属性!$L:$L))} -> 0 | AN12: {=VLOOKUP(K12,技能属性!$A:$Z,15,FALSE)+SUM(_xlfn.XLOOKUP(L12:Z12,增益属性!$A:$A,增益属性!$M:$M))} -> 0
A13: 套装 | B13: 终结技充能 | C13: =VLOOKUP($A$2,干员属性!$A:$AG,10,FALSE)+VLOOKUP($A$4,武器属性!$A:$AB,12,FALSE)+VLOOKUP($A$6,护甲属性!$A:$Z,10,FALSE)+VLOOKUP($A$8,护手属性!$A:$Z,10,FALSE)+VLOOKUP($A$10,配件属性!$A:$Z,10,FALSE)+VLOOKUP($A$12,配件属性!$A:$Z,10,FALSE)+VLOOKUP($A$14,套装属性!$A:$Z,10,FALSE)+VLOOKUP($A$16,食物属性!$A:$Z,10,FALSE) -> 0 | G13: =AA13*AC13*(1+AF13)*(1+AG13)*(1+AH13)*(1+AI13)*(1+AJ13)*(1+AK13)*(1-$D$2+AL13)*(1+AM13)*(1+AN13)*0.5*AE13*J13 -> 0 | H13: =AA13*AC13*(1+AF13)*(1+AG13)*(1+AH13)*(1+AI13)*(1+AJ13)*(1+AK13)*(1-$D$2+AL13)*(1+AM13)*(1+AN13)*0.5*J13 -> 0 | I13: =AA13*AC13*(1+AF13)*(1+AG13)*(1+AH13)*(1+AI13)*(1+AJ13)*(1+AK13)*(1-$D$2+AL13)*(1+AM13)*(1+AN13)*0.5*(AE13*AD13+(1-AD13))*J13 -> 0 | J13: 1 | K13: N/a | L13: N/a | M13: N/a | N13: N/a | O13: N/a | P13: N/a | Q13: N/a | R13: N/a | S13: N/a | T13: N/a | U13: N/a | V13: N/a | W13: N/a | X13: N/a | Y13: N/a | Z13: N/a | AA13: =VLOOKUP(K13,技能属性!$A:$AB,2,FALSE) -> 0 | AB13: {=$C$8+SUM(_xlfn.XLOOKUP(L13:Z13,增益属性!$A:$A,增益属性!$N:$N,0))} -> 0.47 | AC13: {=($C$7*(1+AB13)+$C$27)*(1+(INT((VLOOKUP(VLOOKUP($A$2,干员属性!$A:$AB,24,FALSE),$B$3:$C$6,2,FALSE)/(1+$C$24)*(1+$C$24+SUM(_xlfn.XLOOKUP(L13:Z13,增益属性!$A:$A,增益属性!$O:$O,0)))))*0.5+INT(VLOOKUP(VLOOKUP($A$2,干员属性!$A:$AB,25,FALSE),$B$3:$C$6,2,FALSE)*(1+SUM(_xlfn.XLOOKUP(L13:Z13,增益属性!$A:$A,增益属性!$O:$O,0))))*0.2+(INT(IFERROR(VLOOKUP(VLOOKUP($A$2,干员属性!$A:$AB,26,FALSE),$B$3:$C$6,2,FALSE),0)/(1+$C$25)*(1+$C$25+SUM(_xlfn.XLOOKUP(L13:Z13,增益属性!$A:$A,增益属性!$O:$O,0))))+INT(IFERROR(VLOOKUP(VLOOKUP($A$2,干员属性!$A:$AB,27,FALSE),$B$3:$C$6,2,FALSE),0)*(1+SUM(_xlfn.XLOOKUP(L13:Z13,增益属性!$A:$A,增益属性!$O:$O,0)))))*VLOOKUP($A$2,干员属性!$A:$AB,28,FALSE))/100)} -> 6896.898 | AD13: {=$C$10+VLOOKUP(K13,技能属性!$A:$Z,3,FALSE)+SUM(_xlfn.XLOOKUP(L13:Z13,增益属性!$A:$A,增益属性!$B:$B))} -> 0.16 | AE13: {=$C$11+VLOOKUP(K13,技能属性!$A:$AB,4,FALSE)+SUM(_xlfn.XLOOKUP(L13:Z13,增益属性!$A:$A,增益属性!$C:$C))} -> 1.5 | AF13: {=VLOOKUP(VLOOKUP(K13,技能属性!$A:$Z,5,FALSE),$B$14:$C$18,2,FALSE)+SUM(_xlfn.XLOOKUP(L13:Z13,增益属性!$A:$A,增益属性!$D:$D))+SUM(_xlfn.XLOOKUP(L13:Z13,增益属性!$A:$A,增益属性!$E:$E))+IF(VLOOKUP(K13,技能属性!$A:$Z,6,FALSE)="无",0,VLOOKUP(VLOOKUP(K13,技能属性!$A:$Z,6,FALSE),$B$20:$C$23,2,FALSE))+IF(VLOOKUP(K13,技能属性!$A:$Z,7,FALSE)=0,0,$C$19)} -> 0.7045 | AG13: {=IF(VLOOKUP(K13,技能属性!$A:$Z,8,FALSE)=0,0,$C$12+SUM(_xlfn.XLOOKUP(L13:Z13,增益属性!$A:$A,增益属性!$F:$F)))} -> 0 | AH13: {=VLOOKUP(K13,技能属性!$A:$Z,9,FALSE)+SUM(_xlfn.XLOOKUP(L13:Z13,增益属性!$A:$A,增益属性!$G:$G))} -> 0 | AI13: {=VLOOKUP(K13,技能属性!$A:$Z,10,FALSE)+SUM(_xlfn.XLOOKUP(L13:Z13,增益属性!$A:$A,增益属性!$H:$H))} -> 0 | AJ13: {=VLOOKUP(K13,技能属性!$A:$Z,11,FALSE)+SUM(_xlfn.XLOOKUP(L13:Z13,增益属性!$A:$A,增益属性!$I:$I))} -> 0 | AK13: {=VLOOKUP(K13,技能属性!$A:$Z,12,FALSE)+SUM(_xlfn.XLOOKUP(L13:Z13,增益属性!$A:$A,增益属性!$J:$J))} -> 0 | AL13: {=VLOOKUP(K13,技能属性!$A:$Z,13,FALSE)+SUM(_xlfn.XLOOKUP(L13:Z13,增益属性!$A:$A,增益属性!$K:$K))} -> 0 | AM13: {=VLOOKUP(K13,技能属性!$A:$Z,14,FALSE)+SUM(_xlfn.XLOOKUP(L13:Z13,增益属性!$A:$A,增益属性!$L:$L))} -> 0 | AN13: {=VLOOKUP(K13,技能属性!$A:$Z,15,FALSE)+SUM(_xlfn.XLOOKUP(L13:Z13,增益属性!$A:$A,增益属性!$M:$M))} -> 0
A14: 旧锋 | B14: 物理加成 | C14: =VLOOKUP($A$2,干员属性!$A:$AG,11,FALSE)+VLOOKUP($A$4,武器属性!$A:$AB,13,FALSE)+VLOOKUP($A$6,护甲属性!$A:$Z,11,FALSE)+VLOOKUP($A$8,护手属性!$A:$Z,11,FALSE)+VLOOKUP($A$10,配件属性!$A:$Z,11,FALSE)+VLOOKUP($A$12,配件属性!$A:$Z,11,FALSE)+VLOOKUP($A$14,套装属性!$A:$Z,11,FALSE)+VLOOKUP($A$16,食物属性!$A:$Z,11,FALSE) -> 0.7045 | G14: =AA14*AC14*(1+AF14)*(1+AG14)*(1+AH14)*(1+AI14)*(1+AJ14)*(1+AK14)*(1-$D$2+AL14)*(1+AM14)*(1+AN14)*0.5*AE14*J14 -> 0 | H14: =AA14*AC14*(1+AF14)*(1+AG14)*(1+AH14)*(1+AI14)*(1+AJ14)*(1+AK14)*(1-$D$2+AL14)*(1+AM14)*(1+AN14)*0.5*J14 -> 0 | I14: =AA14*AC14*(1+AF14)*(1+AG14)*(1+AH14)*(1+AI14)*(1+AJ14)*(1+AK14)*(1-$D$2+AL14)*(1+AM14)*(1+AN14)*0.5*(AE14*AD14+(1-AD14))*J14 -> 0 | J14: 1 | K14: N/a | L14: N/a | M14: N/a | N14: N/a | O14: N/a | P14: N/a | Q14: N/a | R14: N/a | S14: N/a | T14: N/a | U14: N/a | V14: N/a | W14: N/a | X14: N/a | Y14: N/a | Z14: N/a | AA14: =VLOOKUP(K14,技能属性!$A:$AB,2,FALSE) -> 0 | AB14: {=$C$8+SUM(_xlfn.XLOOKUP(L14:Z14,增益属性!$A:$A,增益属性!$N:$N,0))} -> 0.47 | AC14: {=($C$7*(1+AB14)+$C$27)*(1+(INT((VLOOKUP(VLOOKUP($A$2,干员属性!$A:$AB,24,FALSE),$B$3:$C$6,2,FALSE)/(1+$C$24)*(1+$C$24+SUM(_xlfn.XLOOKUP(L14:Z14,增益属性!$A:$A,增益属性!$O:$O,0)))))*0.5+INT(VLOOKUP(VLOOKUP($A$2,干员属性!$A:$AB,25,FALSE),$B$3:$C$6,2,FALSE)*(1+SUM(_xlfn.XLOOKUP(L14:Z14,增益属性!$A:$A,增益属性!$O:$O,0))))*0.2+(INT(IFERROR(VLOOKUP(VLOOKUP($A$2,干员属性!$A:$AB,26,FALSE),$B$3:$C$6,2,FALSE),0)/(1+$C$25)*(1+$C$25+SUM(_xlfn.XLOOKUP(L14:Z14,增益属性!$A:$A,增益属性!$O:$O,0))))+INT(IFERROR(VLOOKUP(VLOOKUP($A$2,干员属性!$A:$AB,27,FALSE),$B$3:$C$6,2,FALSE),0)*(1+SUM(_xlfn.XLOOKUP(L14:Z14,增益属性!$A:$A,增益属性!$O:$O,0)))))*VLOOKUP($A$2,干员属性!$A:$AB,28,FALSE))/100)} -> 6896.898 | AD14: {=$C$10+VLOOKUP(K14,技能属性!$A:$Z,3,FALSE)+SUM(_xlfn.XLOOKUP(L14:Z14,增益属性!$A:$A,增益属性!$B:$B))} -> 0.16 | AE14: {=$C$11+VLOOKUP(K14,技能属性!$A:$AB,4,FALSE)+SUM(_xlfn.XLOOKUP(L14:Z14,增益属性!$A:$A,增益属性!$C:$C))} -> 1.5 | AF14: {=VLOOKUP(VLOOKUP(K14,技能属性!$A:$Z,5,FALSE),$B$14:$C$18,2,FALSE)+SUM(_xlfn.XLOOKUP(L14:Z14,增益属性!$A:$A,增益属性!$D:$D))+SUM(_xlfn.XLOOKUP(L14:Z14,增益属性!$A:$A,增益属性!$E:$E))+IF(VLOOKUP(K14,技能属性!$A:$Z,6,FALSE)="无",0,VLOOKUP(VLOOKUP(K14,技能属性!$A:$Z,6,FALSE),$B$20:$C$23,2,FALSE))+IF(VLOOKUP(K14,技能属性!$A:$Z,7,FALSE)=0,0,$C$19)} -> 0.7045 | AG14: {=IF(VLOOKUP(K14,技能属性!$A:$Z,8,FALSE)=0,0,$C$12+SUM(_xlfn.XLOOKUP(L14:Z14,增益属性!$A:$A,增益属性!$F:$F)))} -> 0 | AH14: {=VLOOKUP(K14,技能属性!$A:$Z,9,FALSE)+SUM(_xlfn.XLOOKUP(L14:Z14,增益属性!$A:$A,增益属性!$G:$G))} -> 0 | AI14: {=VLOOKUP(K14,技能属性!$A:$Z,10,FALSE)+SUM(_xlfn.XLOOKUP(L14:Z14,增益属性!$A:$A,增益属性!$H:$H))} -> 0 | AJ14: {=VLOOKUP(K14,技能属性!$A:$Z,11,FALSE)+SUM(_xlfn.XLOOKUP(L14:Z14,增益属性!$A:$A,增益属性!$I:$I))} -> 0 | AK14: {=VLOOKUP(K14,技能属性!$A:$Z,12,FALSE)+SUM(_xlfn.XLOOKUP(L14:Z14,增益属性!$A:$A,增益属性!$J:$J))} -> 0 | AL14: {=VLOOKUP(K14,技能属性!$A:$Z,13,FALSE)+SUM(_xlfn.XLOOKUP(L14:Z14,增益属性!$A:$A,增益属性!$K:$K))} -> 0 | AM14: {=VLOOKUP(K14,技能属性!$A:$Z,14,FALSE)+SUM(_xlfn.XLOOKUP(L14:Z14,增益属性!$A:$A,增益属性!$L:$L))} -> 0 | AN14: {=VLOOKUP(K14,技能属性!$A:$Z,15,FALSE)+SUM(_xlfn.XLOOKUP(L14:Z14,增益属性!$A:$A,增益属性!$M:$M))} -> 0
A15: 食物 | B15: 灼热加成 | C15: =VLOOKUP($A$2,干员属性!$A:$AG,12,FALSE)+VLOOKUP($A$4,武器属性!$A:$AB,14,FALSE)+VLOOKUP($A$6,护甲属性!$A:$Z,12,FALSE)+VLOOKUP($A$8,护手属性!$A:$Z,12,FALSE)+VLOOKUP($A$10,配件属性!$A:$Z,12,FALSE)+VLOOKUP($A$12,配件属性!$A:$Z,12,FALSE)+VLOOKUP($A$14,套装属性!$A:$Z,12,FALSE)+VLOOKUP($A$16,食物属性!$A:$Z,12,FALSE) -> 0 | G15: =AA15*AC15*(1+AF15)*(1+AG15)*(1+AH15)*(1+AI15)*(1+AJ15)*(1+AK15)*(1-$D$2+AL15)*(1+AM15)*(1+AN15)*0.5*AE15*J15 -> 0 | H15: =AA15*AC15*(1+AF15)*(1+AG15)*(1+AH15)*(1+AI15)*(1+AJ15)*(1+AK15)*(1-$D$2+AL15)*(1+AM15)*(1+AN15)*0.5*J15 -> 0 | I15: =AA15*AC15*(1+AF15)*(1+AG15)*(1+AH15)*(1+AI15)*(1+AJ15)*(1+AK15)*(1-$D$2+AL15)*(1+AM15)*(1+AN15)*0.5*(AE15*AD15+(1-AD15))*J15 -> 0 | J15: 1 | K15: N/a | L15: N/a | M15: N/a | N15: N/a | O15: N/a | P15: N/a | Q15: N/a | R15: N/a | S15: N/a | T15: N/a | U15: N/a | V15: N/a | W15: N/a | X15: N/a | Y15: N/a | Z15: N/a | AA15: =VLOOKUP(K15,技能属性!$A:$AB,2,FALSE) -> 0 | AB15: {=$C$8+SUM(_xlfn.XLOOKUP(L15:Z15,增益属性!$A:$A,增益属性!$N:$N,0))} -> 0.47 | AC15: {=($C$7*(1+AB15)+$C$27)*(1+(INT((VLOOKUP(VLOOKUP($A$2,干员属性!$A:$AB,24,FALSE),$B$3:$C$6,2,FALSE)/(1+$C$24)*(1+$C$24+SUM(_xlfn.XLOOKUP(L15:Z15,增益属性!$A:$A,增益属性!$O:$O,0)))))*0.5+INT(VLOOKUP(VLOOKUP($A$2,干员属性!$A:$AB,25,FALSE),$B$3:$C$6,2,FALSE)*(1+SUM(_xlfn.XLOOKUP(L15:Z15,增益属性!$A:$A,增益属性!$O:$O,0))))*0.2+(INT(IFERROR(VLOOKUP(VLOOKUP($A$2,干员属性!$A:$AB,26,FALSE),$B$3:$C$6,2,FALSE),0)/(1+$C$25)*(1+$C$25+SUM(_xlfn.XLOOKUP(L15:Z15,增益属性!$A:$A,增益属性!$O:$O,0))))+INT(IFERROR(VLOOKUP(VLOOKUP($A$2,干员属性!$A:$AB,27,FALSE),$B$3:$C$6,2,FALSE),0)*(1+SUM(_xlfn.XLOOKUP(L15:Z15,增益属性!$A:$A,增益属性!$O:$O,0)))))*VLOOKUP($A$2,干员属性!$A:$AB,28,FALSE))/100)} -> 6896.898 | AD15: {=$C$10+VLOOKUP(K15,技能属性!$A:$Z,3,FALSE)+SUM(_xlfn.XLOOKUP(L15:Z15,增益属性!$A:$A,增益属性!$B:$B))} -> 0.16 | AE15: {=$C$11+VLOOKUP(K15,技能属性!$A:$AB,4,FALSE)+SUM(_xlfn.XLOOKUP(L15:Z15,增益属性!$A:$A,增益属性!$C:$C))} -> 1.5 | AF15: {=VLOOKUP(VLOOKUP(K15,技能属性!$A:$Z,5,FALSE),$B$14:$C$18,2,FALSE)+SUM(_xlfn.XLOOKUP(L15:Z15,增益属性!$A:$A,增益属性!$D:$D))+SUM(_xlfn.XLOOKUP(L15:Z15,增益属性!$A:$A,增益属性!$E:$E))+IF(VLOOKUP(K15,技能属性!$A:$Z,6,FALSE)="无",0,VLOOKUP(VLOOKUP(K15,技能属性!$A:$Z,6,FALSE),$B$20:$C$23,2,FALSE))+IF(VLOOKUP(K15,技能属性!$A:$Z,7,FALSE)=0,0,$C$19)} -> 0.7045 | AG15: {=IF(VLOOKUP(K15,技能属性!$A:$Z,8,FALSE)=0,0,$C$12+SUM(_xlfn.XLOOKUP(L15:Z15,增益属性!$A:$A,增益属性!$F:$F)))} -> 0 | AH15: {=VLOOKUP(K15,技能属性!$A:$Z,9,FALSE)+SUM(_xlfn.XLOOKUP(L15:Z15,增益属性!$A:$A,增益属性!$G:$G))} -> 0 | AI15: {=VLOOKUP(K15,技能属性!$A:$Z,10,FALSE)+SUM(_xlfn.XLOOKUP(L15:Z15,增益属性!$A:$A,增益属性!$H:$H))} -> 0 | AJ15: {=VLOOKUP(K15,技能属性!$A:$Z,11,FALSE)+SUM(_xlfn.XLOOKUP(L15:Z15,增益属性!$A:$A,增益属性!$I:$I))} -> 0 | AK15: {=VLOOKUP(K15,技能属性!$A:$Z,12,FALSE)+SUM(_xlfn.XLOOKUP(L15:Z15,增益属性!$A:$A,增益属性!$J:$J))} -> 0 | AL15: {=VLOOKUP(K15,技能属性!$A:$Z,13,FALSE)+SUM(_xlfn.XLOOKUP(L15:Z15,增益属性!$A:$A,增益属性!$K:$K))} -> 0 | AM15: {=VLOOKUP(K15,技能属性!$A:$Z,14,FALSE)+SUM(_xlfn.XLOOKUP(L15:Z15,增益属性!$A:$A,增益属性!$L:$L))} -> 0 | AN15: {=VLOOKUP(K15,技能属性!$A:$Z,15,FALSE)+SUM(_xlfn.XLOOKUP(L15:Z15,增益属性!$A:$A,增益属性!$M:$M))} -> 0
A16: 清炖兽排参须汤 | B16: 电磁加成 | C16: =VLOOKUP($A$2,干员属性!$A:$AG,13,FALSE)+VLOOKUP($A$4,武器属性!$A:$AB,15,FALSE)+VLOOKUP($A$6,护甲属性!$A:$Z,13,FALSE)+VLOOKUP($A$8,护手属性!$A:$Z,13,FALSE)+VLOOKUP($A$10,配件属性!$A:$Z,13,FALSE)+VLOOKUP($A$12,配件属性!$A:$Z,13,FALSE)+VLOOKUP($A$14,套装属性!$A:$Z,13,FALSE)+VLOOKUP($A$16,食物属性!$A:$Z,13,FALSE) -> 0 | G16: =AA16*AC16*(1+AF16)*(1+AG16)*(1+AH16)*(1+AI16)*(1+AJ16)*(1+AK16)*(1-$D$2+AL16)*(1+AM16)*(1+AN16)*0.5*AE16*J16 -> 0 | H16: =AA16*AC16*(1+AF16)*(1+AG16)*(1+AH16)*(1+AI16)*(1+AJ16)*(1+AK16)*(1-$D$2+AL16)*(1+AM16)*(1+AN16)*0.5*J16 -> 0 | I16: =AA16*AC16*(1+AF16)*(1+AG16)*(1+AH16)*(1+AI16)*(1+AJ16)*(1+AK16)*(1-$D$2+AL16)*(1+AM16)*(1+AN16)*0.5*(AE16*AD16+(1-AD16))*J16 -> 0 | J16: 1 | K16: N/a | L16: N/a | M16: N/a | N16: N/a | O16: N/a | P16: N/a | Q16: N/a | R16: N/a | S16: N/a | T16: N/a | U16: N/a | V16: N/a | W16: N/a | X16: N/a | Y16: N/a | Z16: N/a | AA16: =VLOOKUP(K16,技能属性!$A:$AB,2,FALSE) -> 0 | AB16: {=$C$8+SUM(_xlfn.XLOOKUP(L16:Z16,增益属性!$A:$A,增益属性!$N:$N,0))} -> 0.47 | AC16: {=($C$7*(1+AB16)+$C$27)*(1+(INT((VLOOKUP(VLOOKUP($A$2,干员属性!$A:$AB,24,FALSE),$B$3:$C$6,2,FALSE)/(1+$C$24)*(1+$C$24+SUM(_xlfn.XLOOKUP(L16:Z16,增益属性!$A:$A,增益属性!$O:$O,0)))))*0.5+INT(VLOOKUP(VLOOKUP($A$2,干员属性!$A:$AB,25,FALSE),$B$3:$C$6,2,FALSE)*(1+SUM(_xlfn.XLOOKUP(L16:Z16,增益属性!$A:$A,增益属性!$O:$O,0))))*0.2+(INT(IFERROR(VLOOKUP(VLOOKUP($A$2,干员属性!$A:$AB,26,FALSE),$B$3:$C$6,2,FALSE),0)/(1+$C$25)*(1+$C$25+SUM(_xlfn.XLOOKUP(L16:Z16,增益属性!$A:$A,增益属性!$O:$O,0))))+INT(IFERROR(VLOOKUP(VLOOKUP($A$2,干员属性!$A:$AB,27,FALSE),$B$3:$C$6,2,FALSE),0)*(1+SUM(_xlfn.XLOOKUP(L16:Z16,增益属性!$A:$A,增益属性!$O:$O,0)))))*VLOOKUP($A$2,干员属性!$A:$AB,28,FALSE))/100)} -> 6896.898 | AD16: {=$C$10+VLOOKUP(K16,技能属性!$A:$Z,3,FALSE)+SUM(_xlfn.XLOOKUP(L16:Z16,增益属性!$A:$A,增益属性!$B:$B))} -> 0.16 | AE16: {=$C$11+VLOOKUP(K16,技能属性!$A:$AB,4,FALSE)+SUM(_xlfn.XLOOKUP(L16:Z16,增益属性!$A:$A,增益属性!$C:$C))} -> 1.5 | AF16: {=VLOOKUP(VLOOKUP(K16,技能属性!$A:$Z,5,FALSE),$B$14:$C$18,2,FALSE)+SUM(_xlfn.XLOOKUP(L16:Z16,增益属性!$A:$A,增益属性!$D:$D))+SUM(_xlfn.XLOOKUP(L16:Z16,增益属性!$A:$A,增益属性!$E:$E))+IF(VLOOKUP(K16,技能属性!$A:$Z,6,FALSE)="无",0,VLOOKUP(VLOOKUP(K16,技能属性!$A:$Z,6,FALSE),$B$20:$C$23,2,FALSE))+IF(VLOOKUP(K16,技能属性!$A:$Z,7,FALSE)=0,0,$C$19)} -> 0.7045 | AG16: {=IF(VLOOKUP(K16,技能属性!$A:$Z,8,FALSE)=0,0,$C$12+SUM(_xlfn.XLOOKUP(L16:Z16,增益属性!$A:$A,增益属性!$F:$F)))} -> 0 | AH16: {=VLOOKUP(K16,技能属性!$A:$Z,9,FALSE)+SUM(_xlfn.XLOOKUP(L16:Z16,增益属性!$A:$A,增益属性!$G:$G))} -> 0 | AI16: {=VLOOKUP(K16,技能属性!$A:$Z,10,FALSE)+SUM(_xlfn.XLOOKUP(L16:Z16,增益属性!$A:$A,增益属性!$H:$H))} -> 0 | AJ16: {=VLOOKUP(K16,技能属性!$A:$Z,11,FALSE)+SUM(_xlfn.XLOOKUP(L16:Z16,增益属性!$A:$A,增益属性!$I:$I))} -> 0 | AK16: {=VLOOKUP(K16,技能属性!$A:$Z,12,FALSE)+SUM(_xlfn.XLOOKUP(L16:Z16,增益属性!$A:$A,增益属性!$J:$J))} -> 0 | AL16: {=VLOOKUP(K16,技能属性!$A:$Z,13,FALSE)+SUM(_xlfn.XLOOKUP(L16:Z16,增益属性!$A:$A,增益属性!$K:$K))} -> 0 | AM16: {=VLOOKUP(K16,技能属性!$A:$Z,14,FALSE)+SUM(_xlfn.XLOOKUP(L16:Z16,增益属性!$A:$A,增益属性!$L:$L))} -> 0 | AN16: {=VLOOKUP(K16,技能属性!$A:$Z,15,FALSE)+SUM(_xlfn.XLOOKUP(L16:Z16,增益属性!$A:$A,增益属性!$M:$M))} -> 0
B17: 寒冷加成 | C17: =VLOOKUP($A$2,干员属性!$A:$AG,14,FALSE)+VLOOKUP($A$4,武器属性!$A:$AB,16,FALSE)+VLOOKUP($A$6,护甲属性!$A:$Z,14,FALSE)+VLOOKUP($A$8,护手属性!$A:$Z,14,FALSE)+VLOOKUP($A$10,配件属性!$A:$Z,14,FALSE)+VLOOKUP($A$12,配件属性!$A:$Z,14,FALSE)+VLOOKUP($A$14,套装属性!$A:$Z,14,FALSE)+VLOOKUP($A$16,食物属性!$A:$Z,14,FALSE) -> 0 | G17: =AA17*AC17*(1+AF17)*(1+AG17)*(1+AH17)*(1+AI17)*(1+AJ17)*(1+AK17)*(1-$D$2+AL17)*(1+AM17)*(1+AN17)*0.5*AE17*J17 -> 0 | H17: =AA17*AC17*(1+AF17)*(1+AG17)*(1+AH17)*(1+AI17)*(1+AJ17)*(1+AK17)*(1-$D$2+AL17)*(1+AM17)*(1+AN17)*0.5*J17 -> 0 | I17: =AA17*AC17*(1+AF17)*(1+AG17)*(1+AH17)*(1+AI17)*(1+AJ17)*(1+AK17)*(1-$D$2+AL17)*(1+AM17)*(1+AN17)*0.5*(AE17*AD17+(1-AD17))*J17 -> 0 | J17: 1 | K17: N/a | L17: N/a | M17: N/a | N17: N/a | O17: N/a | P17: N/a | Q17: N/a | R17: N/a | S17: N/a | T17: N/a | U17: N/a | V17: N/a | W17: N/a | X17: N/a | Y17: N/a | Z17: N/a | AA17: =VLOOKUP(K17,技能属性!$A:$AB,2,FALSE) -> 0 | AB17: {=$C$8+SUM(_xlfn.XLOOKUP(L17:Z17,增益属性!$A:$A,增益属性!$N:$N,0))} -> 0.47 | AC17: {=($C$7*(1+AB17)+$C$27)*(1+(INT((VLOOKUP(VLOOKUP($A$2,干员属性!$A:$AB,24,FALSE),$B$3:$C$6,2,FALSE)/(1+$C$24)*(1+$C$24+SUM(_xlfn.XLOOKUP(L17:Z17,增益属性!$A:$A,增益属性!$O:$O,0)))))*0.5+INT(VLOOKUP(VLOOKUP($A$2,干员属性!$A:$AB,25,FALSE),$B$3:$C$6,2,FALSE)*(1+SUM(_xlfn.XLOOKUP(L17:Z17,增益属性!$A:$A,增益属性!$O:$O,0))))*0.2+(INT(IFERROR(VLOOKUP(VLOOKUP($A$2,干员属性!$A:$AB,26,FALSE),$B$3:$C$6,2,FALSE),0)/(1+$C$25)*(1+$C$25+SUM(_xlfn.XLOOKUP(L17:Z17,增益属性!$A:$A,增益属性!$O:$O,0))))+INT(IFERROR(VLOOKUP(VLOOKUP($A$2,干员属性!$A:$AB,27,FALSE),$B$3:$C$6,2,FALSE),0)*(1+SUM(_xlfn.XLOOKUP(L17:Z17,增益属性!$A:$A,增益属性!$O:$O,0)))))*VLOOKUP($A$2,干员属性!$A:$AB,28,FALSE))/100)} -> 6896.898 | AD17: {=$C$10+VLOOKUP(K17,技能属性!$A:$Z,3,FALSE)+SUM(_xlfn.XLOOKUP(L17:Z17,增益属性!$A:$A,增益属性!$B:$B))} -> 0.16 | AE17: {=$C$11+VLOOKUP(K17,技能属性!$A:$AB,4,FALSE)+SUM(_xlfn.XLOOKUP(L17:Z17,增益属性!$A:$A,增益属性!$C:$C))} -> 1.5 | AF17: {=VLOOKUP(VLOOKUP(K17,技能属性!$A:$Z,5,FALSE),$B$14:$C$18,2,FALSE)+SUM(_xlfn.XLOOKUP(L17:Z17,增益属性!$A:$A,增益属性!$D:$D))+SUM(_xlfn.XLOOKUP(L17:Z17,增益属性!$A:$A,增益属性!$E:$E))+IF(VLOOKUP(K17,技能属性!$A:$Z,6,FALSE)="无",0,VLOOKUP(VLOOKUP(K17,技能属性!$A:$Z,6,FALSE),$B$20:$C$23,2,FALSE))+IF(VLOOKUP(K17,技能属性!$A:$Z,7,FALSE)=0,0,$C$19)} -> 0.7045 | AG17: {=IF(VLOOKUP(K17,技能属性!$A:$Z,8,FALSE)=0,0,$C$12+SUM(_xlfn.XLOOKUP(L17:Z17,增益属性!$A:$A,增益属性!$F:$F)))} -> 0 | AH17: {=VLOOKUP(K17,技能属性!$A:$Z,9,FALSE)+SUM(_xlfn.XLOOKUP(L17:Z17,增益属性!$A:$A,增益属性!$G:$G))} -> 0 | AI17: {=VLOOKUP(K17,技能属性!$A:$Z,10,FALSE)+SUM(_xlfn.XLOOKUP(L17:Z17,增益属性!$A:$A,增益属性!$H:$H))} -> 0 | AJ17: {=VLOOKUP(K17,技能属性!$A:$Z,11,FALSE)+SUM(_xlfn.XLOOKUP(L17:Z17,增益属性!$A:$A,增益属性!$I:$I))} -> 0 | AK17: {=VLOOKUP(K17,技能属性!$A:$Z,12,FALSE)+SUM(_xlfn.XLOOKUP(L17:Z17,增益属性!$A:$A,增益属性!$J:$J))} -> 0 | AL17: {=VLOOKUP(K17,技能属性!$A:$Z,13,FALSE)+SUM(_xlfn.XLOOKUP(L17:Z17,增益属性!$A:$A,增益属性!$K:$K))} -> 0 | AM17: {=VLOOKUP(K17,技能属性!$A:$Z,14,FALSE)+SUM(_xlfn.XLOOKUP(L17:Z17,增益属性!$A:$A,增益属性!$L:$L))} -> 0 | AN17: {=VLOOKUP(K17,技能属性!$A:$Z,15,FALSE)+SUM(_xlfn.XLOOKUP(L17:Z17,增益属性!$A:$A,增益属性!$M:$M))} -> 0
B18: 自然加成 | C18: =VLOOKUP($A$2,干员属性!$A:$AG,15,FALSE)+VLOOKUP($A$4,武器属性!$A:$AB,17,FALSE)+VLOOKUP($A$6,护甲属性!$A:$Z,15,FALSE)+VLOOKUP($A$8,护手属性!$A:$Z,15,FALSE)+VLOOKUP($A$10,配件属性!$A:$Z,15,FALSE)+VLOOKUP($A$12,配件属性!$A:$Z,15,FALSE)+VLOOKUP($A$14,套装属性!$A:$Z,15,FALSE)+VLOOKUP($A$16,食物属性!$A:$Z,15,FALSE) -> 0 | G18: =AA18*AC18*(1+AF18)*(1+AG18)*(1+AH18)*(1+AI18)*(1+AJ18)*(1+AK18)*(1-$D$2+AL18)*(1+AM18)*(1+AN18)*0.5*AE18*J18 -> 0 | H18: =AA18*AC18*(1+AF18)*(1+AG18)*(1+AH18)*(1+AI18)*(1+AJ18)*(1+AK18)*(1-$D$2+AL18)*(1+AM18)*(1+AN18)*0.5*J18 -> 0 | I18: =AA18*AC18*(1+AF18)*(1+AG18)*(1+AH18)*(1+AI18)*(1+AJ18)*(1+AK18)*(1-$D$2+AL18)*(1+AM18)*(1+AN18)*0.5*(AE18*AD18+(1-AD18))*J18 -> 0 | J18: 1 | K18: N/a | L18: N/a | M18: N/a | N18: N/a | O18: N/a | P18: N/a | Q18: N/a | R18: N/a | S18: N/a | T18: N/a | U18: N/a | V18: N/a | W18: N/a | X18: N/a | Y18: N/a | Z18: N/a | AA18: =VLOOKUP(K18,技能属性!$A:$AB,2,FALSE) -> 0 | AB18: {=$C$8+SUM(_xlfn.XLOOKUP(L18:Z18,增益属性!$A:$A,增益属性!$N:$N,0))} -> 0.47 | AC18: {=($C$7*(1+AB18)+$C$27)*(1+(INT((VLOOKUP(VLOOKUP($A$2,干员属性!$A:$AB,24,FALSE),$B$3:$C$6,2,FALSE)/(1+$C$24)*(1+$C$24+SUM(_xlfn.XLOOKUP(L18:Z18,增益属性!$A:$A,增益属性!$O:$O,0)))))*0.5+INT(VLOOKUP(VLOOKUP($A$2,干员属性!$A:$AB,25,FALSE),$B$3:$C$6,2,FALSE)*(1+SUM(_xlfn.XLOOKUP(L18:Z18,增益属性!$A:$A,增益属性!$O:$O,0))))*0.2+(INT(IFERROR(VLOOKUP(VLOOKUP($A$2,干员属性!$A:$AB,26,FALSE),$B$3:$C$6,2,FALSE),0)/(1+$C$25)*(1+$C$25+SUM(_xlfn.XLOOKUP(L18:Z18,增益属性!$A:$A,增益属性!$O:$O,0))))+INT(IFERROR(VLOOKUP(VLOOKUP($A$2,干员属性!$A:$AB,27,FALSE),$B$3:$C$6,2,FALSE),0)*(1+SUM(_xlfn.XLOOKUP(L18:Z18,增益属性!$A:$A,增益属性!$O:$O,0)))))*VLOOKUP($A$2,干员属性!$A:$AB,28,FALSE))/100)} -> 6896.898 | AD18: {=$C$10+VLOOKUP(K18,技能属性!$A:$Z,3,FALSE)+SUM(_xlfn.XLOOKUP(L18:Z18,增益属性!$A:$A,增益属性!$B:$B))} -> 0.16 | AE18: {=$C$11+VLOOKUP(K18,技能属性!$A:$AB,4,FALSE)+SUM(_xlfn.XLOOKUP(L18:Z18,增益属性!$A:$A,增益属性!$C:$C))} -> 1.5 | AF18: {=VLOOKUP(VLOOKUP(K18,技能属性!$A:$Z,5,FALSE),$B$14:$C$18,2,FALSE)+SUM(_xlfn.XLOOKUP(L18:Z18,增益属性!$A:$A,增益属性!$D:$D))+SUM(_xlfn.XLOOKUP(L18:Z18,增益属性!$A:$A,增益属性!$E:$E))+IF(VLOOKUP(K18,技能属性!$A:$Z,6,FALSE)="无",0,VLOOKUP(VLOOKUP(K18,技能属性!$A:$Z,6,FALSE),$B$20:$C$23,2,FALSE))+IF(VLOOKUP(K18,技能属性!$A:$Z,7,FALSE)=0,0,$C$19)} -> 0.7045 | AG18: {=IF(VLOOKUP(K18,技能属性!$A:$Z,8,FALSE)=0,0,$C$12+SUM(_xlfn.XLOOKUP(L18:Z18,增益属性!$A:$A,增益属性!$F:$F)))} -> 0 | AH18: {=VLOOKUP(K18,技能属性!$A:$Z,9,FALSE)+SUM(_xlfn.XLOOKUP(L18:Z18,增益属性!$A:$A,增益属性!$G:$G))} -> 0 | AI18: {=VLOOKUP(K18,技能属性!$A:$Z,10,FALSE)+SUM(_xlfn.XLOOKUP(L18:Z18,增益属性!$A:$A,增益属性!$H:$H))} -> 0 | AJ18: {=VLOOKUP(K18,技能属性!$A:$Z,11,FALSE)+SUM(_xlfn.XLOOKUP(L18:Z18,增益属性!$A:$A,增益属性!$I:$I))} -> 0 | AK18: {=VLOOKUP(K18,技能属性!$A:$Z,12,FALSE)+SUM(_xlfn.XLOOKUP(L18:Z18,增益属性!$A:$A,增益属性!$J:$J))} -> 0 | AL18: {=VLOOKUP(K18,技能属性!$A:$Z,13,FALSE)+SUM(_xlfn.XLOOKUP(L18:Z18,增益属性!$A:$A,增益属性!$K:$K))} -> 0 | AM18: {=VLOOKUP(K18,技能属性!$A:$Z,14,FALSE)+SUM(_xlfn.XLOOKUP(L18:Z18,增益属性!$A:$A,增益属性!$L:$L))} -> 0 | AN18: {=VLOOKUP(K18,技能属性!$A:$Z,15,FALSE)+SUM(_xlfn.XLOOKUP(L18:Z18,增益属性!$A:$A,增益属性!$M:$M))} -> 0
B19: 失衡加成 | C19: =VLOOKUP($A$2,干员属性!$A:$AG,17,FALSE)+VLOOKUP($A$4,武器属性!$A:$AB,19,FALSE)+VLOOKUP($A$6,护甲属性!$A:$Z,17,FALSE)+VLOOKUP($A$8,护手属性!$A:$Z,17,FALSE)+VLOOKUP($A$10,配件属性!$A:$Z,17,FALSE)+VLOOKUP($A$12,配件属性!$A:$Z,17,FALSE)+VLOOKUP($A$14,套装属性!$A:$Z,17,FALSE)+VLOOKUP($A$16,食物属性!$A:$Z,17,FALSE) -> 0 | G19: =AA19*AC19*(1+AF19)*(1+AG19)*(1+AH19)*(1+AI19)*(1+AJ19)*(1+AK19)*(1-$D$2+AL19)*(1+AM19)*(1+AN19)*0.5*AE19*J19 -> 0 | H19: =AA19*AC19*(1+AF19)*(1+AG19)*(1+AH19)*(1+AI19)*(1+AJ19)*(1+AK19)*(1-$D$2+AL19)*(1+AM19)*(1+AN19)*0.5*J19 -> 0 | I19: =AA19*AC19*(1+AF19)*(1+AG19)*(1+AH19)*(1+AI19)*(1+AJ19)*(1+AK19)*(1-$D$2+AL19)*(1+AM19)*(1+AN19)*0.5*(AE19*AD19+(1-AD19))*J19 -> 0 | J19: 1 | K19: N/a | L19: N/a | M19: N/a | N19: N/a | O19: N/a | P19: N/a | Q19: N/a | R19: N/a | S19: N/a | T19: N/a | U19: N/a | V19: N/a | W19: N/a | X19: N/a | Y19: N/a | Z19: N/a | AA19: =VLOOKUP(K19,技能属性!$A:$AB,2,FALSE) -> 0 | AB19: {=$C$8+SUM(_xlfn.XLOOKUP(L19:Z19,增益属性!$A:$A,增益属性!$N:$N,0))} -> 0.47 | AC19: {=($C$7*(1+AB19)+$C$27)*(1+(INT((VLOOKUP(VLOOKUP($A$2,干员属性!$A:$AB,24,FALSE),$B$3:$C$6,2,FALSE)/(1+$C$24)*(1+$C$24+SUM(_xlfn.XLOOKUP(L19:Z19,增益属性!$A:$A,增益属性!$O:$O,0)))))*0.5+INT(VLOOKUP(VLOOKUP($A$2,干员属性!$A:$AB,25,FALSE),$B$3:$C$6,2,FALSE)*(1+SUM(_xlfn.XLOOKUP(L19:Z19,增益属性!$A:$A,增益属性!$O:$O,0))))*0.2+(INT(IFERROR(VLOOKUP(VLOOKUP($A$2,干员属性!$A:$AB,26,FALSE),$B$3:$C$6,2,FALSE),0)/(1+$C$25)*(1+$C$25+SUM(_xlfn.XLOOKUP(L19:Z19,增益属性!$A:$A,增益属性!$O:$O,0))))+INT(IFERROR(VLOOKUP(VLOOKUP($A$2,干员属性!$A:$AB,27,FALSE),$B$3:$C$6,2,FALSE),0)*(1+SUM(_xlfn.XLOOKUP(L19:Z19,增益属性!$A:$A,增益属性!$O:$O,0)))))*VLOOKUP($A$2,干员属性!$A:$AB,28,FALSE))/100)} -> 6896.898 | AD19: {=$C$10+VLOOKUP(K19,技能属性!$A:$Z,3,FALSE)+SUM(_xlfn.XLOOKUP(L19:Z19,增益属性!$A:$A,增益属性!$B:$B))} -> 0.16 | AE19: {=$C$11+VLOOKUP(K19,技能属性!$A:$AB,4,FALSE)+SUM(_xlfn.XLOOKUP(L19:Z19,增益属性!$A:$A,增益属性!$C:$C))} -> 1.5 | AF19: {=VLOOKUP(VLOOKUP(K19,技能属性!$A:$Z,5,FALSE),$B$14:$C$18,2,FALSE)+SUM(_xlfn.XLOOKUP(L19:Z19,增益属性!$A:$A,增益属性!$D:$D))+SUM(_xlfn.XLOOKUP(L19:Z19,增益属性!$A:$A,增益属性!$E:$E))+IF(VLOOKUP(K19,技能属性!$A:$Z,6,FALSE)="无",0,VLOOKUP(VLOOKUP(K19,技能属性!$A:$Z,6,FALSE),$B$20:$C$23,2,FALSE))+IF(VLOOKUP(K19,技能属性!$A:$Z,7,FALSE)=0,0,$C$19)} -> 0.7045 | AG19: {=IF(VLOOKUP(K19,技能属性!$A:$Z,8,FALSE)=0,0,$C$12+SUM(_xlfn.XLOOKUP(L19:Z19,增益属性!$A:$A,增益属性!$F:$F)))} -> 0 | AH19: {=VLOOKUP(K19,技能属性!$A:$Z,9,FALSE)+SUM(_xlfn.XLOOKUP(L19:Z19,增益属性!$A:$A,增益属性!$G:$G))} -> 0 | AI19: {=VLOOKUP(K19,技能属性!$A:$Z,10,FALSE)+SUM(_xlfn.XLOOKUP(L19:Z19,增益属性!$A:$A,增益属性!$H:$H))} -> 0 | AJ19: {=VLOOKUP(K19,技能属性!$A:$Z,11,FALSE)+SUM(_xlfn.XLOOKUP(L19:Z19,增益属性!$A:$A,增益属性!$I:$I))} -> 0 | AK19: {=VLOOKUP(K19,技能属性!$A:$Z,12,FALSE)+SUM(_xlfn.XLOOKUP(L19:Z19,增益属性!$A:$A,增益属性!$J:$J))} -> 0 | AL19: {=VLOOKUP(K19,技能属性!$A:$Z,13,FALSE)+SUM(_xlfn.XLOOKUP(L19:Z19,增益属性!$A:$A,增益属性!$K:$K))} -> 0 | AM19: {=VLOOKUP(K19,技能属性!$A:$Z,14,FALSE)+SUM(_xlfn.XLOOKUP(L19:Z19,增益属性!$A:$A,增益属性!$L:$L))} -> 0 | AN19: {=VLOOKUP(K19,技能属性!$A:$Z,15,FALSE)+SUM(_xlfn.XLOOKUP(L19:Z19,增益属性!$A:$A,增益属性!$M:$M))} -> 0
B20: 普攻加成 | C20: =VLOOKUP($A$2,干员属性!$A:$AG,16,FALSE)+VLOOKUP($A$4,武器属性!$A:$AB,18,FALSE)+VLOOKUP($A$6,护甲属性!$A:$Z,16,FALSE)+VLOOKUP($A$8,护手属性!$A:$Z,16,FALSE)+VLOOKUP($A$10,配件属性!$A:$Z,16,FALSE)+VLOOKUP($A$12,配件属性!$A:$Z,16,FALSE)+VLOOKUP($A$14,套装属性!$A:$Z,16,FALSE)+VLOOKUP($A$16,食物属性!$A:$Z,16,FALSE) -> 0 | G20: =AA20*AC20*(1+AF20)*(1+AG20)*(1+AH20)*(1+AI20)*(1+AJ20)*(1+AK20)*(1-$D$2+AL20)*(1+AM20)*(1+AN20)*0.5*AE20*J20 -> 0 | H20: =AA20*AC20*(1+AF20)*(1+AG20)*(1+AH20)*(1+AI20)*(1+AJ20)*(1+AK20)*(1-$D$2+AL20)*(1+AM20)*(1+AN20)*0.5*J20 -> 0 | I20: =AA20*AC20*(1+AF20)*(1+AG20)*(1+AH20)*(1+AI20)*(1+AJ20)*(1+AK20)*(1-$D$2+AL20)*(1+AM20)*(1+AN20)*0.5*(AE20*AD20+(1-AD20))*J20 -> 0 | J20: 1 | K20: N/a | L20: N/a | M20: N/a | N20: N/a | O20: N/a | P20: N/a | Q20: N/a | R20: N/a | S20: N/a | T20: N/a | U20: N/a | V20: N/a | W20: N/a | X20: N/a | Y20: N/a | Z20: N/a | AA20: =VLOOKUP(K20,技能属性!$A:$AB,2,FALSE) -> 0 | AB20: {=$C$8+SUM(_xlfn.XLOOKUP(L20:Z20,增益属性!$A:$A,增益属性!$N:$N,0))} -> 0.47 | AC20: {=($C$7*(1+AB20)+$C$27)*(1+(INT((VLOOKUP(VLOOKUP($A$2,干员属性!$A:$AB,24,FALSE),$B$3:$C$6,2,FALSE)/(1+$C$24)*(1+$C$24+SUM(_xlfn.XLOOKUP(L20:Z20,增益属性!$A:$A,增益属性!$O:$O,0)))))*0.5+INT(VLOOKUP(VLOOKUP($A$2,干员属性!$A:$AB,25,FALSE),$B$3:$C$6,2,FALSE)*(1+SUM(_xlfn.XLOOKUP(L20:Z20,增益属性!$A:$A,增益属性!$O:$O,0))))*0.2+(INT(IFERROR(VLOOKUP(VLOOKUP($A$2,干员属性!$A:$AB,26,FALSE),$B$3:$C$6,2,FALSE),0)/(1+$C$25)*(1+$C$25+SUM(_xlfn.XLOOKUP(L20:Z20,增益属性!$A:$A,增益属性!$O:$O,0))))+INT(IFERROR(VLOOKUP(VLOOKUP($A$2,干员属性!$A:$AB,27,FALSE),$B$3:$C$6,2,FALSE),0)*(1+SUM(_xlfn.XLOOKUP(L20:Z20,增益属性!$A:$A,增益属性!$O:$O,0)))))*VLOOKUP($A$2,干员属性!$A:$AB,28,FALSE))/100)} -> 6896.898 | AD20: {=$C$10+VLOOKUP(K20,技能属性!$A:$Z,3,FALSE)+SUM(_xlfn.XLOOKUP(L20:Z20,增益属性!$A:$A,增益属性!$B:$B))} -> 0.16 | AE20: {=$C$11+VLOOKUP(K20,技能属性!$A:$AB,4,FALSE)+SUM(_xlfn.XLOOKUP(L20:Z20,增益属性!$A:$A,增益属性!$C:$C))} -> 1.5 | AF20: {=VLOOKUP(VLOOKUP(K20,技能属性!$A:$Z,5,FALSE),$B$14:$C$18,2,FALSE)+SUM(_xlfn.XLOOKUP(L20:Z20,增益属性!$A:$A,增益属性!$D:$D))+SUM(_xlfn.XLOOKUP(L20:Z20,增益属性!$A:$A,增益属性!$E:$E))+IF(VLOOKUP(K20,技能属性!$A:$Z,6,FALSE)="无",0,VLOOKUP(VLOOKUP(K20,技能属性!$A:$Z,6,FALSE),$B$20:$C$23,2,FALSE))+IF(VLOOKUP(K20,技能属性!$A:$Z,7,FALSE)=0,0,$C$19)} -> 0.7045 | AG20: {=IF(VLOOKUP(K20,技能属性!$A:$Z,8,FALSE)=0,0,$C$12+SUM(_xlfn.XLOOKUP(L20:Z20,增益属性!$A:$A,增益属性!$F:$F)))} -> 0 | AH20: {=VLOOKUP(K20,技能属性!$A:$Z,9,FALSE)+SUM(_xlfn.XLOOKUP(L20:Z20,增益属性!$A:$A,增益属性!$G:$G))} -> 0 | AI20: {=VLOOKUP(K20,技能属性!$A:$Z,10,FALSE)+SUM(_xlfn.XLOOKUP(L20:Z20,增益属性!$A:$A,增益属性!$H:$H))} -> 0 | AJ20: {=VLOOKUP(K20,技能属性!$A:$Z,11,FALSE)+SUM(_xlfn.XLOOKUP(L20:Z20,增益属性!$A:$A,增益属性!$I:$I))} -> 0 | AK20: {=VLOOKUP(K20,技能属性!$A:$Z,12,FALSE)+SUM(_xlfn.XLOOKUP(L20:Z20,增益属性!$A:$A,增益属性!$J:$J))} -> 0 | AL20: {=VLOOKUP(K20,技能属性!$A:$Z,13,FALSE)+SUM(_xlfn.XLOOKUP(L20:Z20,增益属性!$A:$A,增益属性!$K:$K))} -> 0 | AM20: {=VLOOKUP(K20,技能属性!$A:$Z,14,FALSE)+SUM(_xlfn.XLOOKUP(L20:Z20,增益属性!$A:$A,增益属性!$L:$L))} -> 0 | AN20: {=VLOOKUP(K20,技能属性!$A:$Z,15,FALSE)+SUM(_xlfn.XLOOKUP(L20:Z20,增益属性!$A:$A,增益属性!$M:$M))} -> 0
